Workbook

Sheet Consumer Complaints
A1: Date received | B1: Product | C1: Sub-product | D1: Issue | E1: Sub-issue | F1: Consumer complaint narrative | G1: Company public response | H1: Company | I1: State | J1: ZIP code | K1: Tags | L1: Submitted via | M1: Date sent to company | N1: Company response to consumer | O1: Timely response? | P1: Complaint ID | Q1: Days between sent date and received date
A2: 41046 | B2: Mortgage | C2: Other mortgage | D2: Loan modification,collection,foreclosure | H2: BANK OF AMERICA, NATIONAL ASSOCIATION | I2: CA | J2: 90242 | L2: Referral | M2: 41051 | N2: Closed with non-monetary relief | O2: No | P2: 81081 | Q2: =M2-A2 -> 5
A3: 41142 | B3: Mortgage | C3: Other mortgage | D3: Other | H3: BANK OF AMERICA, NATIONAL ASSOCIATION | I3: NY | J3: 11218 | L3: Postal mail | M3: 41142 | N3: Closed with explanation | O3: Yes | P3: 139273 | Q3: =M3-A3 -> 0
A4: 41264 | B4: Credit card | D4: Advertising and marketing | H4: SYNCHRONY BANK | I4: CA | J4: 91108 | L4: Fax | M4: 41264 | N4: Closed with explanation | O4: Yes | P4: 215434 | Q4: =M4-A4 -> 0
A5: 41274 | B5: Mortgage | C5: Other mortgage | D5: Loan modification,collection,foreclosure | H5: OCWEN LOAN SERVICING LLC | I5: MI | J5: 48320 | L5: Fax | M5: 41276 | N5: Closed with explanation | O5: Yes | P5: 215643 | Q5: =M5-A5 -> 2
A6: 41283 | B6: Mortgage | C6: Other mortgage | D6: Loan modification,collection,foreclosure | H6: WELLS FARGO BANK, NATIONAL ASSOCIATION | I6: CA | J6: 94590 | L6: Referral | M6: 41288 | N6: Closed with explanation | O6: Yes | P6: 224922 | Q6: =M6-A6 -> 5
A7: 41473 | B7: Debt collection | C7: Medical | D7: Cont'd attempts collect debt not owed | E7: Debt is not mine | H7: APEX Asset Management, LLC | I7: NJ | J7: 8031 | L7: Web | M7: 41509 | N7: Closed | O7: No | P7: 460443 | Q7: =M7-A7 -> 36
A8: 41826 | B8: Mortgage | C8: Conventional adjustable mortgage (ARM) | D8: Loan servicing, payments, escrow account | H8: Ditech Financial LLC | I8: FL | J8: 34714 | L8: Web | M8: 41826 | N8: Closed with explanation | O8: Yes | P8: 924254 | Q8: =M8-A8 -> 0
A9: 41884 | B9: Credit reporting | D9: Incorrect information on credit report | E9: Public record | H9: TRANSUNION INTERMEDIATE HOLDINGS, INC. | I9: FL | J9: 33928 | L9: Web | M9: 41884 | N9: Closed with explanation | O9: Yes | P9: 1009652 | Q9: =M9-A9 -> 0
A10: 41932 | B10: Credit card | D10: Identity theft / Fraud / Embezzlement | H10: SYNCHRONY BANK | I10: CA | J10: 91602 | L10: Postal mail | M10: 41936 | N10: Closed with explanation | O10: Yes | P10: 1077763 | Q10: =M10-A10 -> 4
A11: 41935 | B11: Mortgage | C11: Other mortgage | D11: Loan modification,collection,foreclosure | H11: BANK OF AMERICA, NATIONAL ASSOCIATION | I11: CA | J11: 92879 | L11: Referral | M11: 41940 | N11: Closed with explanation | O11: Yes | P11: 1084242 | Q11: =M11-A11 -> 5
A12: 42008 | B12: Consumer Loan | C12: Installment loan | D12: Managing the loan or lease | H12: SYNCHRONY BANK | I12: NJ | J12: 8901 | L12: Web | M12: 42012 | N12: Closed with monetary relief | O12: Yes | P12: 1179936 | Q12: =M12-A12 -> 4
A13: 42065 | B13: Debt collection | C13: Non-federal student loan | D13: Disclosure verification of debt | E13: Not disclosed as an attempt to collect | H13: Law Offices of Goldsmith & Hull A.P.C. | I13: CA | J13: 90008 | L13: Postal mail | M13: 42072 | N13: Closed with explanation | O13: No | P13: 1263989 | Q13: =M13-A13 -> 7
A14: 42355 | B14: Debt collection | C14: Medical | D14: Disclosure verification of debt | E14: Not given enough info to verify debt | H14: Alpine Credit, Inc | I14: CO | J14: 80017 | L14: Web | M14: 42355 | N14: Closed with explanation | O14: No | P14: 1706577 | Q14: =M14-A14 -> 0
A15: 42408 | B15: Credit reporting | D15: Incorrect information on credit report | E15: Account status | G15: Company chooses not to provide a public response | H15: EXPERIAN DELAWARE GP | I15: NC | J15: 27703 | L15: Postal mail | M15: 42408 | N15: Closed with explanation | O15: Yes | P15: 1776912 | Q15: =M15-A15 -> 0
A16: 42454 | B16: Debt collection | C16: Other (i.e. phone, health club, etc.) | D16: Disclosure verification of debt | E16: Not given enough info to verify debt | H16: Quality Recovery Services, Inc. | I16: GA | J16: 30014 | L16: Referral | M16: 42458 | N16: Closed with explanation | O16: No | P16: 1849932 | Q16: =M16-A16 -> 4
A17: 42489 | B17: Credit reporting | D17: Incorrect information on credit report | E17: Information is not mine | G17: Company has responded to the consumer and the CFPB and chooses not to provide a public response | H17: TRANSUNION INTERMEDIATE HOLDINGS, INC. | I17: NV | J17: 89031 | L17: Web | M17: 42489 | N17: Closed with explanation | O17: Yes | P17: 1901482 | Q17: =M17-A17 -> 0
A18: 42496 | B18: Debt collection | C18: Other (i.e. phone, health club, etc.) | D18: Cont'd attempts collect debt not owed | E18: Debt is not mine | F18: i gave a vehicle away signed a bill of sale and turned in a release of liability to the dmv 6 plus years after i have a report on my XXXX that i have a XXXX dollar debt for the vehicle after it was impounded.i contacted the reporting persons and was told that because the other party had not followed through i was responsible even though the XXXX couldnt find a record of me owning the vehicle.i tried working with this company providing all the info i could for them even though the dmv wasnt able to find my name attached to this vehicle and refused to investagate anything | H18: FINEX Group LLC | I18: CA | J18: 953XX | L18: Web | M18: 42496 | N18: Closed with explanation | O18: No | P18: 1914423 | Q18: =M18-A18 -> 0
A19: 42508 | B19: Mortgage | C19: Other mortgage | D19: Loan modification,collection,foreclosure | G19: Company has responded to the consumer and the CFPB and chooses not to provide a public response | H19: WELLS FARGO BANK, NATIONAL ASSOCIATION | I19: NJ | J19: 8618 | L19: Referral | M19: 42513 | N19: Closed with explanation | O19: Yes | P19: 1931957 | Q19: =M19-A19 -> 5
A20: 42549 | B20: Debt collection | C20: Other (i.e. phone, health club, etc.) | D20: Taking/threatening an illegal action | E20: Threatened to sue on too old debt | H20: Resurgent Capital Services L.P. | I20: MI | J20: 48219 | L20: Referral | M20: 42550 | N20: Closed with explanation | O20: Yes | P20: 1989521 | Q20: =M20-A20 -> 1
A21: 42682 | B21: Credit reporting | D21: Incorrect information on credit report | E21: Information is not mine | H21: EQUIFAX, INC. | I21: AZ | J21: 85296 | L21: Web | M21: 42682 | N21: Closed with explanation | O21: Yes | P21: 2199513 | Q21: =M21-A21 -> 0
A22: 42691 | B22: Debt collection | C22: Other (i.e. phone, health club, etc.) | D22: Disclosure verification of debt | E22: Not given enough info to verify debt | H22: PMGI, LLC | I22: CA | J22: 92356 | L22: Postal mail | M22: 42692 | N22: Closed with non-monetary relief | O22: No | P22: 2214174 | Q22: =M22-A22 -> 1
A23: 42692 | B23: Mortgage | C23: Conventional fixed mortgage | D23: Settlement process and costs | F23: Started the refinance of home mortgage process with cash out option on XX/XX/2016. Necessary documents were submitted by XXXX. After initial review, got good faith estimate with loan amount and closing cost. Based on this estimate, a deposit of {$350.00} was made towards appraisal. Appraisal came with lesser amount by {$5000.00}. Agreed to reduce the loan amount to that extent. However, got a revised estimate which was less by {$30000.00} and with additional closing cost towards points etc. In between got numerous revised estimates with different loan amounts and closing cost. It took more than 2 months to reach any definite closing document. Hence, want to get back the deposit of {$350.00}. | H23: AMERICAN NEIGHBORHOOD MORTGAGE | I23: NJ | J23: 088XX | L23: Web | M23: 42695 | N23: Closed with monetary relief | O23: No | P23: 2216206 | Q23: =M23-A23 -> 3
A24: 42699 | B24: Debt collection | C24: Other (i.e. phone, health club, etc.) | D24: Disclosure verification of debt | E24: Not given enough info to verify debt | H24: RR Resource-Recovery | I24: NY | J24: 13760 | L24: Web | M24: 42798 | N24: Closed with explanation | O24: Yes | P24: 2223190 | Q24: =M24-A24 -> 99
A25: 42772 | B25: Consumer Loan | C25: Installment loan | D25: Managing the loan or lease | F25: I have written to this company called Swiss Colony and disputed the item on my credit report and requested them to provide documentation bearing my signature associate with the account. They did not do so. I also let them know that the account may be fraudulent as well. I have an fraud alert on my credit files because of this company. I have looked at my credit report dated today ( XX/XX/2017 ) and before that date I did n't see the statement disputed by consumer in the remark area on my credit files. Instead in the remark area : Profit and loss write off. This statement is in the remark area. This company has broken the law called FCRA because they failed to place the statement : " disputed by consumer, '' and I do want the company to delete the entry from my credit files. I have requested this company to provide proof of any documentations bearing my signature with this account. They failed to do so with that being said I want the entry to be deleted immediately. | H25: Colony Brands, Inc. | I25: NC | J25: 278XX | L25: Web | M25: 42798 | N25: Untimely response | O25: No | P25: 2329445 | Q25: =M25-A25 -> 26
A26: 42794 | B26: Debt collection | C26: Other (i.e. phone, health club, etc.) | D26: Improper contact or sharing of info | E26: Contacted me after I asked not to | H26: EXPERT GLOBAL SOLUTIONS, INC. | L26: Web | M26: 42798 | N26: Closed with explanation | O26: Yes | P26: 2364897 | Q26: =M26-A26 -> 4
A27: 42795 | B27: Debt collection | C27: I do not know | D27: Improper contact or sharing of info | E27: Talked to a third party about my debt | H27: Bursey & Associates, P.C. | I27: AZ | J27: 85295 | L27: Web | M27: 42798 | N27: Closed with explanation | O27: Yes | P27: 2367513 | Q27: =M27-A27 -> 3
A28: 42795 | B28: Student loan | C28: Federal student loan servicing | D28: Dealing with my lender or servicer | E28: Trouble with how payments are handled | H28: AES/PHEAA | L28: Referral | M28: 42802 | N28: Closed with explanation | O28: Yes | P28: 2367674 | Q28: =M28-A28 -> 7
A29: 42796 | B29: Mortgage | C29: Conventional fixed mortgage | D29: Loan servicing, payments, escrow account | H29: Dovenmuehle Mortgage, Inc. | I29: CT | J29: 6360 | L29: Phone | M29: 42800 | N29: Closed with explanation | O29: Yes | P29: 2369802 | Q29: =M29-A29 -> 4
A30: 42798 | B30: Mortgage | C30: Conventional fixed mortgage | D30: Loan servicing, payments, escrow account | G30: Company believes it acted appropriately as authorized by contract or law | H30: Ditech Financial LLC | I30: MI | J30: 48328 | L30: Web | M30: 42798 | N30: Closed with explanation | O30: Yes | P30: 2371574 | Q30: =M30-A30 -> 0
A31: 42798 | B31: Debt collection | C31: Credit card | D31: Cont'd attempts collect debt not owed | E31: Debt is not mine | H31: Levy and Associates, LLC | I31: OH | J31: 43235 | L31: Web | M31: 42798 | N31: Closed with explanation | O31: Yes | P31: 2371593 | Q31: =M31-A31 -> 0
A32: 42798 | B32: Credit reporting | D32: Credit reporting company's investigation | E32: Inadequate help over the phone | H32: EQUIFAX, INC. | I32: NY | J32: 14610 | L32: Web | M32: 42798 | N32: Closed with explanation | O32: Yes | P32: 2371598 | Q32: =M32-A32 -> 0
A33: 42798 | B33: Debt collection | C33: Credit card | D33: Cont'd attempts collect debt not owed | E33: Debt resulted from identity theft | H33: Credit Card Receivables Fund Incorporated | I33: NC | J33: 27597 | L33: Web | M33: 42798 | N33: Closed with explanation | O33: Yes | P33: 2371600 | Q33: =M33-A33 -> 0
A34: 42798 | B34: Credit card | D34: Balance transfer | F34: Around XX/XX/XXXX I accepted a credit card offer from my Chase AARP card at a 0 % interest for a year with a 2 % transfer fee. Needing the money, I called Chase and asked them to deposit XXXX into my checking account and, shortly there after, they did so. Now, they are wanting the XXXX. back from my checking account. They say it was their error but they should n't have deposited the money because that checking account has n't been used to pay a Chase fee within 3 months, so could n't be approved for the transfer.. I had XXXX balances so there was no need to make a payment. They made this decision after they deposited the money into my account.They say they will pay the bank fees but where am I supposed to get the XXXX?. I do not have all of the XXXX left and what is there is allocated for checks and payments that have not cleared yet. I accepted their offer and borrowed this money in good faith and have spent many hours on the phone with various Chase reps and am that the account is active, has XXXX available credit, but they can not assign the money already borrowed to that account because it was n't used for 3 months. Surely they can lift the rule to cover their error, but they wo n't. The woman, who said she was a manager, gave me the fax number of Chase Executive Offices as my only recourse. So, I am contacting you. This is an AARP card, available only to XXXX. They are causing havoc in my life and do not care at all. Please help | H34: JPMORGAN CHASE & CO. | I34: TN | J34: 376XX | K34: Older American | L34: Web | M34: 42798 | N34: Closed with monetary relief | O34: Yes | P34: 2371616 | Q34: =M34-A34 -> 0
A35: 42798 | B35: Mortgage | C35: Other mortgage | D35: Loan modification,collection,foreclosure | H35: JPMORGAN CHASE & CO. | I35: NC | J35: 28731 | K35: Older American | L35: Web | M35: 42798 | N35: Closed with explanation | O35: Yes | P35: 2371632 | Q35: =M35-A35 -> 0
A36: 42798 | B36: Bank account or service | C36: Other bank product/service | D36: Using a debit or ATM card | H36: Comerica | I36: NC | J36: 28405 | L36: Web | M36: 42798 | N36: Closed with explanation | O36: Yes | P36: 2371634 | Q36: =M36-A36 -> 0
A37: 42798 | B37: Debt collection | C37: Credit card | D37: Cont'd attempts collect debt not owed | E37: Debt resulted from identity theft | H37: ONEMAIN FINANCIAL HOLDINGS, LLC. | I37: NC | J37: 27597 | L37: Web | M37: 42798 | N37: Closed with explanation | O37: Yes | P37: 2371642 | Q37: =M37-A37 -> 0
A38: 42798 | B38: Credit reporting | D38: Credit reporting company's investigation | E38: Investigation took too long | H38: EQUIFAX, INC. | I38: CA | J38: 92683 | L38: Web | M38: 42798 | N38: Closed with explanation | O38: Yes | P38: 2371648 | Q38: =M38-A38 -> 0
A39: 42798 | B39: Student loan | C39: Federal student loan servicing | D39: Can't repay my loan | E39: Can't get flexible payment options | F39: I filed for chapter XXXX bankruptcy XX/XX/2011. I did go to school after filing. Notice of filing was provided to the Federal Loan employees when they called every week. They have continued to report late history on my credit report. A call was placed to them two weeks ago to address the issue with reporting negative payments. The rep stated they would correct as payments should have not been reported. When the reports were checked, it was noted that the accounts were reported as current under negative account information on XXXX, and showing 11 missed payments for the past two years on XXXX and XXXX reports. They should not be reporting negatively to any credit bureaus due to the active bankruptcy. The information should also be reported under the correct sections of the credit file. I am asking that the company report the information accurately on all the credit files as it has really added to the negative standard of my credit score | H39: AES/PHEAA | I39: TN | J39: 381XX | L39: Web | M39: 42798 | N39: Closed with explanation | O39: Yes | P39: 2371677 | Q39: =M39-A39 -> 0
A40: 42798 | B40: Debt collection | C40: Credit card | D40: Disclosure verification of debt | E40: Not given enough info to verify debt | H40: ONEMAIN FINANCIAL HOLDINGS, LLC. | I40: NC | J40: 27597 | L40: Web | M40: 42798 | N40: Closed with explanation | O40: Yes | P40: 2371691 | Q40: =M40-A40 -> 0
...

Sheet Geographical Insights
A1: State | B1: Number of complaints per state | C1: Perchentage of complaints per state | D1: Perchentage of complaints per state(rounded)
A2: AL | B2: =COUNTIF('Consumer Complaints'!I2:I201,'Geographical Insights'!A2) -> 1 | C2: =B2/SUM($B$2:$B$39) -> 0.0053763441 | D2: =_xlfn.CEILING.MATH(C2,0.01) -> 0.01
A3: AR | B3: =COUNTIF('Consumer Complaints'!I3:I202,'Geographical Insights'!A3) -> 1 | C3: =B3/SUM($B$2:$B$39) -> 0.0053763441 | D3: =_xlfn.CEILING.MATH(C3,0.01) -> 0.01
A4: AZ | B4: =COUNTIF('Consumer Complaints'!I4:I203,'Geographical Insights'!A4) -> 7 | C4: =B4/SUM($B$2:$B$39) -> 0.037634409 | D4: =_xlfn.CEILING.MATH(C4,0.01) -> 0.04
A5: CA | B5: =COUNTIF('Consumer Complaints'!I5:I204,'Geographical Insights'!A5) -> 25 | C5: =B5/SUM($B$2:$B$39) -> 0.1344086 | D5: =_xlfn.CEILING.MATH(C5,0.01) -> 0.14
A6: CO | B6: =COUNTIF('Consumer Complaints'!I6:I205,'Geographical Insights'!A6) -> 3 | C6: =B6/SUM($B$2:$B$39) -> 0.016129032 | D6: =_xlfn.CEILING.MATH(C6,0.01) -> 0.02
A7: CT | B7: =COUNTIF('Consumer Complaints'!I7:I206,'Geographical Insights'!A7) -> 2 | C7: =B7/SUM($B$2:$B$39) -> 0.010752688 | D7: =_xlfn.CEILING.MATH(C7,0.01) -> 0.02
A8: DC | B8: =COUNTIF('Consumer Complaints'!I8:I207,'Geographical Insights'!A8) -> 4 | C8: =B8/SUM($B$2:$B$39) -> 0.021505376 | D8: =_xlfn.CEILING.MATH(C8,0.01) -> 0.03
A9: FL | B9: =COUNTIF('Consumer Complaints'!I9:I208,'Geographical Insights'!A9) -> 10 | C9: =B9/SUM($B$2:$B$39) -> 0.053763441 | D9: =_xlfn.CEILING.MATH(C9,0.01) -> 0.06
A10: GA | B10: =COUNTIF('Consumer Complaints'!I10:I209,'Geographical Insights'!A10) -> 11 | C10: =B10/SUM($B$2:$B$39) -> 0.059139785 | D10: =_xlfn.CEILING.MATH(C10,0.01) -> 0.06
A11: IA | B11: =COUNTIF('Consumer Complaints'!I11:I210,'Geographical Insights'!A11) -> 1 | C11: =B11/SUM($B$2:$B$39) -> 0.0053763441 | D11: =_xlfn.CEILING.MATH(C11,0.01) -> 0.01
A12: IL | B12: =COUNTIF('Consumer Complaints'!I12:I211,'Geographical Insights'!A12) -> 7 | C12: =B12/SUM($B$2:$B$39) -> 0.037634409 | D12: =_xlfn.CEILING.MATH(C12,0.01) -> 0.04
A13: IN | B13: =COUNTIF('Consumer Complaints'!I13:I212,'Geographical Insights'!A13) -> 3 | C13: =B13/SUM($B$2:$B$39) -> 0.016129032 | D13: =_xlfn.CEILING.MATH(C13,0.01) -> 0.02
... A39: WI | B39: =COUNTIF('Consumer Complaints'!I39:I238,'Geographical Insights'!A39) -> 3 | C39: =B39/SUM($B$2:$B$39) -> 0.016129032 | D39: =_xlfn.CEILING.MATH(C39,0.01) -> 0.02

Sheet Statistical Insights
A1: Distinct Issue | E1: unici
A2: Incorrect information on credit report | E2: {=_xlfn.UNIQUE(A2:A201)} -> Incorrect information on credit report | F2: =COUNTIF($A$2:$A$201,E2) -> 22
A3: Disclosure verification of debt | E3: Disclosure verification of debt | F3: =COUNTIF($A$2:$A$201,E3) -> 19
A4: Other | E4: Other | F4: =COUNTIF($A$2:$A$201,E4) -> 5
A5: Loan modification,collection,foreclosure | E5: Loan modification,collection,foreclosure | F5: =COUNTIF($A$2:$A$201,E5) -> 14
A6: Credit determination | E6: Credit determination | F6: =COUNTIF($A$2:$A$201,E6) -> 3
A7: Disclosure verification of debt | E7: Loan servicing, payments, escrow account | F7: =COUNTIF($A$2:$A$201,E7) -> 22
A8: Loan servicing, payments, escrow account | B8: ="Moda = "&E2&";"&E7 -> Moda = Incorrect information on credit report;Loan servicing, payments, escrow account | E8: Making/receiving payments, sending money | F8: =COUNTIF($A$2:$A$201,E8) -> 4
A9: Loan modification,collection,foreclosure | E9: Settlement process and costs | F9: =COUNTIF($A$2:$A$201,E9) -> 1
A10: Making/receiving payments, sending money | E10: Dealing with my lender or servicer | F10: =COUNTIF($A$2:$A$201,E10) -> 5
A11: Settlement process and costs | E11: Fraud or scam | F11: =COUNTIF($A$2:$A$201,E11) -> 2
A12: Dealing with my lender or servicer | E12: Account opening, closing, or management | F12: =COUNTIF($A$2:$A$201,E12) -> 16
A13: Fraud or scam | E13: Can't repay my loan | F13: =COUNTIF($A$2:$A$201,E13) -> 5
A14: Disclosure verification of debt | E14: Problems when you are unable to pay | F14: =COUNTIF($A$2:$A$201,E14) -> 4
A15: Loan modification,collection,foreclosure | E15: Credit reporting company's investigation | F15: =COUNTIF($A$2:$A$201,E15) -> 3
A16: Account opening, closing, or management | E16: Other fee | F16: =COUNTIF($A$2:$A$201,E16) -> 2
A17: Loan servicing, payments, escrow account | E17: Advertising, marketing or disclosures | F17: =COUNTIF($A$2:$A$201,E17) -> 1
A18: Loan modification,collection,foreclosure | E18: Improper contact or sharing of info | F18: =COUNTIF($A$2:$A$201,E18) -> 3
A19: Account opening, closing, or management | E19: Identity theft / Fraud / Embezzlement | F19: =COUNTIF($A$2:$A$201,E19) -> 5
A20: Can't repay my loan | E20: Customer service / Customer relations | F20: =COUNTIF($A$2:$A$201,E20) -> 1
... A46: Loan servicing, payments, escrow account | E46: Lost or stolen money order | F46: =COUNTIF($A$2:$A$201,E46) -> 1
A47: Loan modification,collection,foreclosure
A48: Problems caused by my funds being low
A49: Deposits and withdrawals
A50: Other
A51: Incorrect information on credit report
A52: Managing the loan or lease
A53: APR or interest rate
A54: Disclosure verification of debt
A55: Incorrect information on credit report
A56: Incorrect information on credit report
A57: Making/receiving payments, sending money
A58: Loan modification,collection,foreclosure
... A201: Incorrect information on credit report
