Workbook

Sheet Parameters
A1: Probability | B1: Mean | C1: StdDev
A2: 0.61154136 | B2: 53 | C2: 15.23

Sheet Data
A1: Age | B1: Group
A2: =INT(_xlfn.NORM.INV(RAND(),Parameters!$B$2,Parameters!$C$2)) -> 59 | B2: =RANDBETWEEN(1,4) -> 4
A3: =INT(_xlfn.NORM.INV(RAND(),Parameters!$B$2,Parameters!$C$2)) -> 59 | B3: =RANDBETWEEN(1,4) -> 3
A4: =INT(_xlfn.NORM.INV(RAND(),Parameters!$B$2,Parameters!$C$2)) -> 53 | B4: =RANDBETWEEN(1,4) -> 1
A5: =INT(_xlfn.NORM.INV(RAND(),Parameters!$B$2,Parameters!$C$2)) -> 61 | B5: =RANDBETWEEN(1,4) -> 1
A6: =INT(_xlfn.NORM.INV(RAND(),Parameters!$B$2,Parameters!$C$2)) -> 57 | B6: =RANDBETWEEN(1,4) -> 1
A7: =INT(_xlfn.NORM.INV(RAND(),Parameters!$B$2,Parameters!$C$2)) -> 45 | B7: =RANDBETWEEN(1,4) -> 1
A8: =INT(_xlfn.NORM.INV(RAND(),Parameters!$B$2,Parameters!$C$2)) -> 48 | B8: =RANDBETWEEN(1,4) -> 3
A9: =INT(_xlfn.NORM.INV(RAND(),Parameters!$B$2,Parameters!$C$2)) -> 28 | B9: =RANDBETWEEN(1,4) -> 1
A10: =INT(_xlfn.NORM.INV(RAND(),Parameters!$B$2,Parameters!$C$2)) -> 63 | B10: =RANDBETWEEN(1,4) -> 2
A11: =INT(_xlfn.NORM.INV(RAND(),Parameters!$B$2,Parameters!$C$2)) -> 48 | B11: =RANDBETWEEN(1,4) -> 1
A12: =INT(_xlfn.NORM.INV(RAND(),Parameters!$B$2,Parameters!$C$2)) -> 19 | B12: =RANDBETWEEN(1,4) -> 3
A13: =INT(_xlfn.NORM.INV(RAND(),Parameters!$B$2,Parameters!$C$2)) -> 64 | B13: =RANDBETWEEN(1,4) -> 3
... A251: =INT(_xlfn.NORM.INV(RAND(),Parameters!$B$2,Parameters!$C$2)) -> 32 | B251: =RANDBETWEEN(1,4) -> 1

Sheet Sample
A1: Age | B1: Group | C1: Sample
A2: =Data!A2 -> 59 | B2: =Data!B2 -> 4 | C2: =IF(B2=1,"YES","NO") -> NO
A3: =Data!A3 -> 59 | B3: =Data!B3 -> 3 | C3: =IF(B3=1,"YES","NO") -> NO
A4: =Data!A4 -> 53 | B4: =Data!B4 -> 1 | C4: =IF(B4=1,"YES","NO") -> YES
A5: =Data!A5 -> 61 | B5: =Data!B5 -> 1 | C5: =IF(B5=1,"YES","NO") -> YES
A6: =Data!A6 -> 57 | B6: =Data!B6 -> 1 | C6: =IF(B6=1,"YES","NO") -> YES
A7: =Data!A7 -> 45 | B7: =Data!B7 -> 1 | C7: =IF(B7=1,"YES","NO") -> YES
A8: =Data!A8 -> 48 | B8: =Data!B8 -> 3 | C8: =IF(B8=1,"YES","NO") -> NO
A9: =Data!A9 -> 28 | B9: =Data!B9 -> 1 | C9: =IF(B9=1,"YES","NO") -> YES
A10: =Data!A10 -> 63 | B10: =Data!B10 -> 2 | C10: =IF(B10=1,"YES","NO") -> NO
A11: =Data!A11 -> 48 | B11: =Data!B11 -> 1 | C11: =IF(B11=1,"YES","NO") -> YES
A12: =Data!A12 -> 19 | B12: =Data!B12 -> 3 | C12: =IF(B12=1,"YES","NO") -> NO
A13: =Data!A13 -> 64 | B13: =Data!B13 -> 3 | C13: =IF(B13=1,"YES","NO") -> NO
... A251: =Data!A251 -> 32 | B251: =Data!B251 -> 1 | C251: =IF(B251=1,"YES","NO") -> YES

Sheet Statistical Insight
A1: Sample | B1: STDDEV | C1: EXPECTED VALUE | D1: COUNT | E1: CONFIDENCE RATE | F1: Estimation of p parameter | G1: Confidence Interval | H1: Z
A2: 48 | B2: =ROUND(SQRT(_xlfn.VAR.S(Data!A2:A251)),2) -> 15.59 | C2: =AVERAGE(Data!A2:A251) -> 51.812 | D2: =COUNT(A2:A65) -> 64 | E2: 0.95 | F2: =ROUND(2*MIN(_xlfn.Z.TEST(A2:A65,C2),1-_xlfn.Z.TEST(A2:A65,C2)),3) -> 0.39 | G2: ="[" & ROUND(C2 - 1.96 * (B2 / SQRT(D2)), 2) & " - " & ROUND(C2 + 1.96 * (B2 / SQRT(D2)), 2) & "]" -> [47,99 - 55,63] | H2: =(AVERAGE(A2:A65)-'Statistical Insight'!C2)/('Statistical Insight'!B2/SQRT('Statistical Insight'!D2)) -> 0.93033996
A3: 31
A4: 73 | C4: Il sotto-campione analizzato è composto da 64 individui, appartenenti al gruppo 1 della popolazione. La media campionaria del sotto-campione è pari a 53,63. Con il test Z andiamo a confrontare la media campionaria con quella della popolazione per stabilire se sono significativamente diverse o meno. L'intervallo critico è pari a [-1,96;1,96] per un livello di confidenza pari al 95% e il valore Z ottenuto è pari a 0,959. Z ricade nell'intervallo quindi possiamo affermare che la media campionaria è uguale a quella della popolazione.
A5: 31
A6: 55
A7: 36
A8: 30
A9: 31
A10: 34
A11: 42
A12: 43
A13: 19
A14: 57
A15: 48
A16: 55
... A65: 57

Sheet (Un)correlated Variables
A1: Sample data | B1: Number of cats | C1: Age of partner | AF1: Test | DU1: Test
A2: 48 | B2: 18 | C2: 37 | F2: CATS | T2: CATS | AF2: H0: X uncorrelated Y | AI2: AGE OF PARTNER | CC2: AGE OF PARTNER | DU2: H0: X uncorrelated Y
A3: 31 | B3: 8 | C3: 44 | F3: 1 | G3: 2 | H3: 3 | I3: 4 | J3: 5 | K3: 6 | L3: 7 | M3: 8 | N3: 9 | O3: 10 | P3: Marginal | T3: 1 | U3: 2 | V3: 3 | W3: 4 | X3: 5 | Y3: 6 | Z3: 7 | AA3: 8 | AB3: 9 | AC3: 10 | AD3: Marginal | AF3: H1:X correlated Y | AJ3: 37 | AK3: 44 | AL3: 54 | AM3: 41 | AN3: 39 | AO3: 65 | AP3: 46 | AQ3: 75 | AR3: 68 | AS3: 77 | AT3: 63 | AU3: 42 | AV3: 30 | AW3: 78 | AX3: 53 | AY3: 71 | AZ3: 80 | BA3: 74 | BB3: 69 | BC3: 48 | BD3: 60 | BE3: 64 | BF3: 24 | BG3: 22 | BH3: 25 | BI3: 72 | BJ3: 47 | BK3: 21 | BL3: 70 | BM3: 34 | BN3: 32 | BO3: 38 | BP3: 55 | BQ3: 61 | BR3: 57 | BS3: 52 | BT3: 27 | BU3: 23 | BV3: 79 | BW3: 33 | BX3: 76 | BY3: Marginal | CD3: 37 | CE3: 44 | CF3: 54 | CG3: 41 | CH3: 39 | CI3: 65 | CJ3: 46 | CK3: 75 | CL3: 68 | CM3: 77 | CN3: 63 | CO3: 42 | CP3: 30 | CQ3: 78 | CR3: 53 | CS3: 71 | CT3: 80 | CU3: 74 | CV3: 69 | CW3: 48 | CX3: 60 | CY3: 64 | CZ3: 24 | DA3: 22 | DB3: 25 | DC3: 72 | DD3: 47 | DE3: 21 | DF3: 70 | DG3: 34 | DH3: 32 | DI3: 38 | DJ3: 55 | DK3: 61 | DL3: 57 | DM3: 52 | DN3: 27 | DO3: 23 | DP3: 79 | DQ3: 33 | DR3: 76 | DS3: Marginal | DU3: H1:X correlated Y
A4: 73 | B4: 7 | C4: 54 | D4: AGE | E4: {=_xlfn.UNIQUE(A2:A65)} -> 48 | F4: =COUNTIFS($A$2:$A$65,$E4,$B$2:$B$65,F$3) -> 0 | G4: =COUNTIFS($A$2:$A$65,$E4,$B$2:$B$65,G$3) -> 0 | H4: =COUNTIFS($A$2:$A$65,$E4,$B$2:$B$65,H$3) -> 0 | I4: =COUNTIFS($A$2:$A$65,$E4,$B$2:$B$65,I$3) -> 0 | J4: =COUNTIFS($A$2:$A$65,$E4,$B$2:$B$65,J$3) -> 0 | K4: =COUNTIFS($A$2:$A$65,$E4,$B$2:$B$65,K$3) -> 0 | L4: =COUNTIFS($A$2:$A$65,$E4,$B$2:$B$65,L$3) -> 0 | M4: =COUNTIFS($A$2:$A$65,$E4,$B$2:$B$65,M$3) -> 0 | ... O4: =COUNTIFS($A$2:$A$65,$E4,$B$2:$B$65,O$3) -> 0 | P4: =SUM(F4:O4) -> 0 | R4: AGE | S4: 41 | T4: =ROUND($AD4*T$47/$AD$47,3) -> 0.344 | U4: =ROUND($AD4*U$47/$AD$47,3) -> 0.188 | V4: =ROUND($AD4*V$47/$AD$47,3) -> 0.156 | W4: =ROUND($AD4*W$47/$AD$47,3) -> 0.25 | X4: =ROUND($AD4*X$47/$AD$47,3) -> 0.156 | Y4: =ROUND($AD4*Y$47/$AD$47,3) -> 0.156 | Z4: =ROUND($AD4*Z$47/$AD$47,3) -> 0.125 | AA4: =ROUND($AD4*AA$47/$AD$47,3) -> 0.156 | ... AC4: =ROUND($AD4*AC$47/$AD$47,3) -> 0.25 | AD4: 2 | AF4: ="Test="&_xlfn.CHISQ.TEST(F4:O46,T4:AC46) -> Test=0,999999155277458 | AH4: AGE | AI4: 41 | AJ4: =COUNTIFS($A$2:$A$65,$AI4,$C$2:$C$65,AJ$3) -> 0 | AK4: =COUNTIFS($A$2:$A$65,$AI4,$C$2:$C$65,AK$3) -> 0 | AL4: =COUNTIFS($A$2:$A$65,$AI4,$C$2:$C$65,AL$3) -> 0 | AM4: =COUNTIFS($A$2:$A$65,$AI4,$C$2:$C$65,AM$3) -> 0 | AN4: =COUNTIFS($A$2:$A$65,$AI4,$C$2:$C$65,AN$3) -> 1 | AO4: =COUNTIFS($A$2:$A$65,$AI4,$C$2:$C$65,AO$3) -> 0 | AP4: =COUNTIFS($A$2:$A$65,$AI4,$C$2:$C$65,AP$3) -> 0 | AQ4: =COUNTIFS($A$2:$A$65,$AI4,$C$2:$C$65,AQ$3) -> 0 | ... BX4: =COUNTIFS($A$2:$A$65,$AI4,$C$2:$C$65,BX$3) -> 0 | BY4: =SUM(AJ4:BX4) -> 1 | CB4: AGE | CC4: 41 | CD4: =$DS4*CD$47/$DS$47 -> 0.03125 | CE4: =$DS4*CE$47/$DS$47 -> 0.03125 | CF4: =$DS4*CF$47/$DS$47 -> 0.03125 | CG4: =$DS4*CG$47/$DS$47 -> 0.0625 | CH4: =$DS4*CH$47/$DS$47 -> 0.0625 | CI4: =$DS4*CI$47/$DS$47 -> 0.0625 | CJ4: =$DS4*CJ$47/$DS$47 -> 0.03125 | CK4: =$DS4*CK$47/$DS$47 -> 0.09375 | ... DR4: =$DS4*DR$47/$DS$47 -> 0.03125 | DS4: 2 | DU4: ="Test=" -> Test=
A5: 31 | B5: 13 | C5: 41 | E5: 31 | F5: =COUNTIFS($A$2:$A$65,$E5,$B$2:$B$65,F$3) -> 0 | G5: =COUNTIFS($A$2:$A$65,$E5,$B$2:$B$65,G$3) -> 0 | H5: =COUNTIFS($A$2:$A$65,$E5,$B$2:$B$65,H$3) -> 0 | I5: =COUNTIFS($A$2:$A$65,$E5,$B$2:$B$65,I$3) -> 0 | J5: =COUNTIFS($A$2:$A$65,$E5,$B$2:$B$65,J$3) -> 0 | K5: =COUNTIFS($A$2:$A$65,$E5,$B$2:$B$65,K$3) -> 0 | L5: =COUNTIFS($A$2:$A$65,$E5,$B$2:$B$65,L$3) -> 1 | M5: =COUNTIFS($A$2:$A$65,$E5,$B$2:$B$65,M$3) -> 1 | ... O5: =COUNTIFS($A$2:$A$65,$E5,$B$2:$B$65,O$3) -> 0 | P5: =SUM(F5:O5) -> 2 | S5: 27 | T5: =ROUND($AD5*T$47/$AD$47,3) -> 0.172 | U5: =ROUND($AD5*U$47/$AD$47,3) -> 0.094 | V5: =ROUND($AD5*V$47/$AD$47,3) -> 0.078 | W5: =ROUND($AD5*W$47/$AD$47,3) -> 0.125 | X5: =ROUND($AD5*X$47/$AD$47,3) -> 0.078 | Y5: =ROUND($AD5*Y$47/$AD$47,3) -> 0.078 | Z5: =ROUND($AD5*Z$47/$AD$47,3) -> 0.063 | AA5: =ROUND($AD5*AA$47/$AD$47,3) -> 0.078 | ... AC5: =ROUND($AD5*AC$47/$AD$47,3) -> 0.125 | AD5: 1 | AF5: Test>0,05 - H0 verified | AI5: 27 | AJ5: =COUNTIFS($A$2:$A$65,$AI5,$C$2:$C$65,AJ$3) -> 0 | AK5: =COUNTIFS($A$2:$A$65,$AI5,$C$2:$C$65,AK$3) -> 0 | AL5: =COUNTIFS($A$2:$A$65,$AI5,$C$2:$C$65,AL$3) -> 0 | AM5: =COUNTIFS($A$2:$A$65,$AI5,$C$2:$C$65,AM$3) -> 0 | AN5: =COUNTIFS($A$2:$A$65,$AI5,$C$2:$C$65,AN$3) -> 0 | AO5: =COUNTIFS($A$2:$A$65,$AI5,$C$2:$C$65,AO$3) -> 0 | AP5: =COUNTIFS($A$2:$A$65,$AI5,$C$2:$C$65,AP$3) -> 0 | AQ5: =COUNTIFS($A$2:$A$65,$AI5,$C$2:$C$65,AQ$3) -> 0 | ... BX5: =COUNTIFS($A$2:$A$65,$AI5,$C$2:$C$65,BX$3) -> 0 | BY5: =SUM(AJ5:BX5) -> 0 | CC5: 27 | CD5: =$DS5*CD$47/$DS$47 -> 0.015625 | CE5: =$DS5*CE$47/$DS$47 -> 0.015625 | CF5: =$DS5*CF$47/$DS$47 -> 0.015625 | CG5: =$DS5*CG$47/$DS$47 -> 0.03125 | CH5: =$DS5*CH$47/$DS$47 -> 0.03125 | CI5: =$DS5*CI$47/$DS$47 -> 0.03125 | CJ5: =$DS5*CJ$47/$DS$47 -> 0.015625 | CK5: =$DS5*CK$47/$DS$47 -> 0.046875 | ... DR5: =$DS5*DR$47/$DS$47 -> 0.015625 | DS5: 1 | DU5: Test>0,05 - H0 verified
A6: 55 | B6: 17 | C6: 39 | E6: 73 | F6: =COUNTIFS($A$2:$A$65,$E6,$B$2:$B$65,F$3) -> 1 | G6: =COUNTIFS($A$2:$A$65,$E6,$B$2:$B$65,G$3) -> 0 | H6: =COUNTIFS($A$2:$A$65,$E6,$B$2:$B$65,H$3) -> 1 | I6: =COUNTIFS($A$2:$A$65,$E6,$B$2:$B$65,I$3) -> 0 | J6: =COUNTIFS($A$2:$A$65,$E6,$B$2:$B$65,J$3) -> 0 | K6: =COUNTIFS($A$2:$A$65,$E6,$B$2:$B$65,K$3) -> 0 | L6: =COUNTIFS($A$2:$A$65,$E6,$B$2:$B$65,L$3) -> 1 | M6: =COUNTIFS($A$2:$A$65,$E6,$B$2:$B$65,M$3) -> 0 | ... O6: =COUNTIFS($A$2:$A$65,$E6,$B$2:$B$65,O$3) -> 0 | P6: =SUM(F6:O6) -> 3 | S6: 32 | T6: =ROUND($AD6*T$47/$AD$47,3) -> 0.344 | U6: =ROUND($AD6*U$47/$AD$47,3) -> 0.188 | V6: =ROUND($AD6*V$47/$AD$47,3) -> 0.156 | W6: =ROUND($AD6*W$47/$AD$47,3) -> 0.25 | X6: =ROUND($AD6*X$47/$AD$47,3) -> 0.156 | Y6: =ROUND($AD6*Y$47/$AD$47,3) -> 0.156 | Z6: =ROUND($AD6*Z$47/$AD$47,3) -> 0.125 | AA6: =ROUND($AD6*AA$47/$AD$47,3) -> 0.156 | ... AC6: =ROUND($AD6*AC$47/$AD$47,3) -> 0.25 | AD6: 2 | AI6: 32 | AJ6: =COUNTIFS($A$2:$A$65,$AI6,$C$2:$C$65,AJ$3) -> 0 | AK6: =COUNTIFS($A$2:$A$65,$AI6,$C$2:$C$65,AK$3) -> 0 | AL6: =COUNTIFS($A$2:$A$65,$AI6,$C$2:$C$65,AL$3) -> 0 | AM6: =COUNTIFS($A$2:$A$65,$AI6,$C$2:$C$65,AM$3) -> 0 | AN6: =COUNTIFS($A$2:$A$65,$AI6,$C$2:$C$65,AN$3) -> 0 | AO6: =COUNTIFS($A$2:$A$65,$AI6,$C$2:$C$65,AO$3) -> 0 | AP6: =COUNTIFS($A$2:$A$65,$AI6,$C$2:$C$65,AP$3) -> 0 | AQ6: =COUNTIFS($A$2:$A$65,$AI6,$C$2:$C$65,AQ$3) -> 0 | ... BX6: =COUNTIFS($A$2:$A$65,$AI6,$C$2:$C$65,BX$3) -> 0 | BY6: =SUM(AJ6:BX6) -> 0 | CC6: 32 | CD6: =$DS6*CD$47/$DS$47 -> 0.03125 | CE6: =$DS6*CE$47/$DS$47 -> 0.03125 | CF6: =$DS6*CF$47/$DS$47 -> 0.03125 | CG6: =$DS6*CG$47/$DS$47 -> 0.0625 | CH6: =$DS6*CH$47/$DS$47 -> 0.0625 | CI6: =$DS6*CI$47/$DS$47 -> 0.0625 | CJ6: =$DS6*CJ$47/$DS$47 -> 0.03125 | CK6: =$DS6*CK$47/$DS$47 -> 0.09375 | ... DR6: =$DS6*DR$47/$DS$47 -> 0.03125 | DS6: 2
A7: 36 | B7: 6 | C7: 65 | E7: 55 | F7: =COUNTIFS($A$2:$A$65,$E7,$B$2:$B$65,F$3) -> 0 | G7: =COUNTIFS($A$2:$A$65,$E7,$B$2:$B$65,G$3) -> 0 | H7: =COUNTIFS($A$2:$A$65,$E7,$B$2:$B$65,H$3) -> 0 | I7: =COUNTIFS($A$2:$A$65,$E7,$B$2:$B$65,I$3) -> 0 | J7: =COUNTIFS($A$2:$A$65,$E7,$B$2:$B$65,J$3) -> 0 | K7: =COUNTIFS($A$2:$A$65,$E7,$B$2:$B$65,K$3) -> 0 | L7: =COUNTIFS($A$2:$A$65,$E7,$B$2:$B$65,L$3) -> 0 | M7: =COUNTIFS($A$2:$A$65,$E7,$B$2:$B$65,M$3) -> 0 | ... O7: =COUNTIFS($A$2:$A$65,$E7,$B$2:$B$65,O$3) -> 0 | P7: =SUM(F7:O7) -> 0 | S7: 57 | T7: =ROUND($AD7*T$47/$AD$47,3) -> 0.344 | U7: =ROUND($AD7*U$47/$AD$47,3) -> 0.188 | V7: =ROUND($AD7*V$47/$AD$47,3) -> 0.156 | W7: =ROUND($AD7*W$47/$AD$47,3) -> 0.25 | X7: =ROUND($AD7*X$47/$AD$47,3) -> 0.156 | Y7: =ROUND($AD7*Y$47/$AD$47,3) -> 0.156 | Z7: =ROUND($AD7*Z$47/$AD$47,3) -> 0.125 | AA7: =ROUND($AD7*AA$47/$AD$47,3) -> 0.156 | ... AC7: =ROUND($AD7*AC$47/$AD$47,3) -> 0.25 | AD7: 2 | AF7: ="Correlazion Age VS Number of cats:"&ROUND(PEARSON(A2:A65,B2:B65),3) -> Correlazion Age VS Number of cats:-0,08 | AI7: 57 | AJ7: =COUNTIFS($A$2:$A$65,$AI7,$C$2:$C$65,AJ$3) -> 0 | AK7: =COUNTIFS($A$2:$A$65,$AI7,$C$2:$C$65,AK$3) -> 0 | AL7: =COUNTIFS($A$2:$A$65,$AI7,$C$2:$C$65,AL$3) -> 0 | AM7: =COUNTIFS($A$2:$A$65,$AI7,$C$2:$C$65,AM$3) -> 0 | AN7: =COUNTIFS($A$2:$A$65,$AI7,$C$2:$C$65,AN$3) -> 0 | AO7: =COUNTIFS($A$2:$A$65,$AI7,$C$2:$C$65,AO$3) -> 0 | AP7: =COUNTIFS($A$2:$A$65,$AI7,$C$2:$C$65,AP$3) -> 0 | AQ7: =COUNTIFS($A$2:$A$65,$AI7,$C$2:$C$65,AQ$3) -> 0 | ... BX7: =COUNTIFS($A$2:$A$65,$AI7,$C$2:$C$65,BX$3) -> 1 | BY7: =SUM(AJ7:BX7) -> 2 | CC7: 57 | CD7: =$DS7*CD$47/$DS$47 -> 0.03125 | CE7: =$DS7*CE$47/$DS$47 -> 0.03125 | CF7: =$DS7*CF$47/$DS$47 -> 0.03125 | CG7: =$DS7*CG$47/$DS$47 -> 0.0625 | CH7: =$DS7*CH$47/$DS$47 -> 0.0625 | CI7: =$DS7*CI$47/$DS$47 -> 0.0625 | CJ7: =$DS7*CJ$47/$DS$47 -> 0.03125 | CK7: =$DS7*CK$47/$DS$47 -> 0.09375 | ... DR7: =$DS7*DR$47/$DS$47 -> 0.03125 | DS7: 2
A8: 30 | B8: 6 | C8: 46 | E8: 36 | F8: =COUNTIFS($A$2:$A$65,$E8,$B$2:$B$65,F$3) -> 0 | G8: =COUNTIFS($A$2:$A$65,$E8,$B$2:$B$65,G$3) -> 0 | H8: =COUNTIFS($A$2:$A$65,$E8,$B$2:$B$65,H$3) -> 0 | I8: =COUNTIFS($A$2:$A$65,$E8,$B$2:$B$65,I$3) -> 0 | J8: =COUNTIFS($A$2:$A$65,$E8,$B$2:$B$65,J$3) -> 0 | K8: =COUNTIFS($A$2:$A$65,$E8,$B$2:$B$65,K$3) -> 1 | L8: =COUNTIFS($A$2:$A$65,$E8,$B$2:$B$65,L$3) -> 0 | M8: =COUNTIFS($A$2:$A$65,$E8,$B$2:$B$65,M$3) -> 0 | ... O8: =COUNTIFS($A$2:$A$65,$E8,$B$2:$B$65,O$3) -> 0 | P8: =SUM(F8:O8) -> 1 | S8: 46 | T8: =ROUND($AD8*T$47/$AD$47,3) -> 0.172 | U8: =ROUND($AD8*U$47/$AD$47,3) -> 0.094 | V8: =ROUND($AD8*V$47/$AD$47,3) -> 0.078 | W8: =ROUND($AD8*W$47/$AD$47,3) -> 0.125 | X8: =ROUND($AD8*X$47/$AD$47,3) -> 0.078 | Y8: =ROUND($AD8*Y$47/$AD$47,3) -> 0.078 | Z8: =ROUND($AD8*Z$47/$AD$47,3) -> 0.063 | AA8: =ROUND($AD8*AA$47/$AD$47,3) -> 0.078 | ... AC8: =ROUND($AD8*AC$47/$AD$47,3) -> 0.125 | AD8: 1 | AF8: X uncorrelated Y | AI8: 46 | AJ8: =COUNTIFS($A$2:$A$65,$AI8,$C$2:$C$65,AJ$3) -> 0 | AK8: =COUNTIFS($A$2:$A$65,$AI8,$C$2:$C$65,AK$3) -> 0 | AL8: =COUNTIFS($A$2:$A$65,$AI8,$C$2:$C$65,AL$3) -> 0 | AM8: =COUNTIFS($A$2:$A$65,$AI8,$C$2:$C$65,AM$3) -> 0 | AN8: =COUNTIFS($A$2:$A$65,$AI8,$C$2:$C$65,AN$3) -> 0 | AO8: =COUNTIFS($A$2:$A$65,$AI8,$C$2:$C$65,AO$3) -> 0 | AP8: =COUNTIFS($A$2:$A$65,$AI8,$C$2:$C$65,AP$3) -> 0 | AQ8: =COUNTIFS($A$2:$A$65,$AI8,$C$2:$C$65,AQ$3) -> 0 | ... BX8: =COUNTIFS($A$2:$A$65,$AI8,$C$2:$C$65,BX$3) -> 0 | BY8: =SUM(AJ8:BX8) -> 0 | CC8: 46 | CD8: =$DS8*CD$47/$DS$47 -> 0.015625 | CE8: =$DS8*CE$47/$DS$47 -> 0.015625 | CF8: =$DS8*CF$47/$DS$47 -> 0.015625 | CG8: =$DS8*CG$47/$DS$47 -> 0.03125 | CH8: =$DS8*CH$47/$DS$47 -> 0.03125 | CI8: =$DS8*CI$47/$DS$47 -> 0.03125 | CJ8: =$DS8*CJ$47/$DS$47 -> 0.015625 | CK8: =$DS8*CK$47/$DS$47 -> 0.046875 | ... DR8: =$DS8*DR$47/$DS$47 -> 0.015625 | DS8: 1 | DU8: ="Correlazion Age VS Number of cats:"&ROUND(PEARSON(A2:A65,C2:C65),3) -> Correlazion Age VS Number of cats:-0,011
A9: 31 | B9: 7 | C9: 75 | E9: 30 | F9: =COUNTIFS($A$2:$A$65,$E9,$B$2:$B$65,F$3) -> 0 | G9: =COUNTIFS($A$2:$A$65,$E9,$B$2:$B$65,G$3) -> 0 | H9: =COUNTIFS($A$2:$A$65,$E9,$B$2:$B$65,H$3) -> 0 | I9: =COUNTIFS($A$2:$A$65,$E9,$B$2:$B$65,I$3) -> 0 | J9: =COUNTIFS($A$2:$A$65,$E9,$B$2:$B$65,J$3) -> 0 | K9: =COUNTIFS($A$2:$A$65,$E9,$B$2:$B$65,K$3) -> 1 | L9: =COUNTIFS($A$2:$A$65,$E9,$B$2:$B$65,L$3) -> 0 | M9: =COUNTIFS($A$2:$A$65,$E9,$B$2:$B$65,M$3) -> 0 | ... O9: =COUNTIFS($A$2:$A$65,$E9,$B$2:$B$65,O$3) -> 0 | P9: =SUM(F9:O9) -> 1 | S9: 26 | T9: =ROUND($AD9*T$47/$AD$47,3) -> 0.344 | U9: =ROUND($AD9*U$47/$AD$47,3) -> 0.188 | V9: =ROUND($AD9*V$47/$AD$47,3) -> 0.156 | W9: =ROUND($AD9*W$47/$AD$47,3) -> 0.25 | X9: =ROUND($AD9*X$47/$AD$47,3) -> 0.156 | Y9: =ROUND($AD9*Y$47/$AD$47,3) -> 0.156 | Z9: =ROUND($AD9*Z$47/$AD$47,3) -> 0.125 | AA9: =ROUND($AD9*AA$47/$AD$47,3) -> 0.156 | ... AC9: =ROUND($AD9*AC$47/$AD$47,3) -> 0.25 | AD9: 2 | AI9: 26 | AJ9: =COUNTIFS($A$2:$A$65,$AI9,$C$2:$C$65,AJ$3) -> 0 | AK9: =COUNTIFS($A$2:$A$65,$AI9,$C$2:$C$65,AK$3) -> 0 | AL9: =COUNTIFS($A$2:$A$65,$AI9,$C$2:$C$65,AL$3) -> 0 | AM9: =COUNTIFS($A$2:$A$65,$AI9,$C$2:$C$65,AM$3) -> 0 | AN9: =COUNTIFS($A$2:$A$65,$AI9,$C$2:$C$65,AN$3) -> 0 | AO9: =COUNTIFS($A$2:$A$65,$AI9,$C$2:$C$65,AO$3) -> 0 | AP9: =COUNTIFS($A$2:$A$65,$AI9,$C$2:$C$65,AP$3) -> 0 | AQ9: =COUNTIFS($A$2:$A$65,$AI9,$C$2:$C$65,AQ$3) -> 0 | ... BX9: =COUNTIFS($A$2:$A$65,$AI9,$C$2:$C$65,BX$3) -> 0 | BY9: =SUM(AJ9:BX9) -> 0 | CC9: 26 | CD9: =$DS9*CD$47/$DS$47 -> 0.03125 | CE9: =$DS9*CE$47/$DS$47 -> 0.03125 | CF9: =$DS9*CF$47/$DS$47 -> 0.03125 | CG9: =$DS9*CG$47/$DS$47 -> 0.0625 | CH9: =$DS9*CH$47/$DS$47 -> 0.0625 | CI9: =$DS9*CI$47/$DS$47 -> 0.0625 | CJ9: =$DS9*CJ$47/$DS$47 -> 0.03125 | CK9: =$DS9*CK$47/$DS$47 -> 0.09375 | ... DR9: =$DS9*DR$47/$DS$47 -> 0.03125 | DS9: 2 | DU9: X uncorrelated Y
A10: 34 | B10: 10 | C10: 68 | E10: 34 | F10: =COUNTIFS($A$2:$A$65,$E10,$B$2:$B$65,F$3) -> 0 | G10: =COUNTIFS($A$2:$A$65,$E10,$B$2:$B$65,G$3) -> 0 | H10: =COUNTIFS($A$2:$A$65,$E10,$B$2:$B$65,H$3) -> 0 | I10: =COUNTIFS($A$2:$A$65,$E10,$B$2:$B$65,I$3) -> 0 | J10: =COUNTIFS($A$2:$A$65,$E10,$B$2:$B$65,J$3) -> 0 | K10: =COUNTIFS($A$2:$A$65,$E10,$B$2:$B$65,K$3) -> 0 | L10: =COUNTIFS($A$2:$A$65,$E10,$B$2:$B$65,L$3) -> 0 | M10: =COUNTIFS($A$2:$A$65,$E10,$B$2:$B$65,M$3) -> 0 | ... O10: =COUNTIFS($A$2:$A$65,$E10,$B$2:$B$65,O$3) -> 1 | P10: =SUM(F10:O10) -> 1 | S10: 79 | T10: =ROUND($AD10*T$47/$AD$47,3) -> 0.344 | U10: =ROUND($AD10*U$47/$AD$47,3) -> 0.188 | V10: =ROUND($AD10*V$47/$AD$47,3) -> 0.156 | W10: =ROUND($AD10*W$47/$AD$47,3) -> 0.25 | X10: =ROUND($AD10*X$47/$AD$47,3) -> 0.156 | Y10: =ROUND($AD10*Y$47/$AD$47,3) -> 0.156 | Z10: =ROUND($AD10*Z$47/$AD$47,3) -> 0.125 | AA10: =ROUND($AD10*AA$47/$AD$47,3) -> 0.156 | ... AC10: =ROUND($AD10*AC$47/$AD$47,3) -> 0.25 | AD10: 2 | AI10: 79 | AJ10: =COUNTIFS($A$2:$A$65,$AI10,$C$2:$C$65,AJ$3) -> 0 | AK10: =COUNTIFS($A$2:$A$65,$AI10,$C$2:$C$65,AK$3) -> 0 | AL10: =COUNTIFS($A$2:$A$65,$AI10,$C$2:$C$65,AL$3) -> 0 | AM10: =COUNTIFS($A$2:$A$65,$AI10,$C$2:$C$65,AM$3) -> 0 | AN10: =COUNTIFS($A$2:$A$65,$AI10,$C$2:$C$65,AN$3) -> 0 | AO10: =COUNTIFS($A$2:$A$65,$AI10,$C$2:$C$65,AO$3) -> 0 | AP10: =COUNTIFS($A$2:$A$65,$AI10,$C$2:$C$65,AP$3) -> 0 | AQ10: =COUNTIFS($A$2:$A$65,$AI10,$C$2:$C$65,AQ$3) -> 0 | ... BX10: =COUNTIFS($A$2:$A$65,$AI10,$C$2:$C$65,BX$3) -> 0 | BY10: =SUM(AJ10:BX10) -> 0 | CC10: 79 | CD10: =$DS10*CD$47/$DS$47 -> 0.03125 | CE10: =$DS10*CE$47/$DS$47 -> 0.03125 | CF10: =$DS10*CF$47/$DS$47 -> 0.03125 | CG10: =$DS10*CG$47/$DS$47 -> 0.0625 | CH10: =$DS10*CH$47/$DS$47 -> 0.0625 | CI10: =$DS10*CI$47/$DS$47 -> 0.0625 | CJ10: =$DS10*CJ$47/$DS$47 -> 0.03125 | CK10: =$DS10*CK$47/$DS$47 -> 0.09375 | ... DR10: =$DS10*DR$47/$DS$47 -> 0.03125 | DS10: 2
A11: 42 | B11: 8 | C11: 77 | E11: 42 | F11: =COUNTIFS($A$2:$A$65,$E11,$B$2:$B$65,F$3) -> 0 | G11: =COUNTIFS($A$2:$A$65,$E11,$B$2:$B$65,G$3) -> 1 | H11: =COUNTIFS($A$2:$A$65,$E11,$B$2:$B$65,H$3) -> 0 | I11: =COUNTIFS($A$2:$A$65,$E11,$B$2:$B$65,I$3) -> 0 | J11: =COUNTIFS($A$2:$A$65,$E11,$B$2:$B$65,J$3) -> 0 | K11: =COUNTIFS($A$2:$A$65,$E11,$B$2:$B$65,K$3) -> 0 | L11: =COUNTIFS($A$2:$A$65,$E11,$B$2:$B$65,L$3) -> 0 | M11: =COUNTIFS($A$2:$A$65,$E11,$B$2:$B$65,M$3) -> 1 | ... O11: =COUNTIFS($A$2:$A$65,$E11,$B$2:$B$65,O$3) -> 0 | P11: =SUM(F11:O11) -> 2 | S11: 59 | T11: =ROUND($AD11*T$47/$AD$47,3) -> 0.344 | U11: =ROUND($AD11*U$47/$AD$47,3) -> 0.188 | V11: =ROUND($AD11*V$47/$AD$47,3) -> 0.156 | W11: =ROUND($AD11*W$47/$AD$47,3) -> 0.25 | X11: =ROUND($AD11*X$47/$AD$47,3) -> 0.156 | Y11: =ROUND($AD11*Y$47/$AD$47,3) -> 0.156 | Z11: =ROUND($AD11*Z$47/$AD$47,3) -> 0.125 | AA11: =ROUND($AD11*AA$47/$AD$47,3) -> 0.156 | ... AC11: =ROUND($AD11*AC$47/$AD$47,3) -> 0.25 | AD11: 2 | AI11: 59 | AJ11: =COUNTIFS($A$2:$A$65,$AI11,$C$2:$C$65,AJ$3) -> 0 | AK11: =COUNTIFS($A$2:$A$65,$AI11,$C$2:$C$65,AK$3) -> 0 | AL11: =COUNTIFS($A$2:$A$65,$AI11,$C$2:$C$65,AL$3) -> 0 | AM11: =COUNTIFS($A$2:$A$65,$AI11,$C$2:$C$65,AM$3) -> 0 | AN11: =COUNTIFS($A$2:$A$65,$AI11,$C$2:$C$65,AN$3) -> 0 | AO11: =COUNTIFS($A$2:$A$65,$AI11,$C$2:$C$65,AO$3) -> 0 | AP11: =COUNTIFS($A$2:$A$65,$AI11,$C$2:$C$65,AP$3) -> 0 | AQ11: =COUNTIFS($A$2:$A$65,$AI11,$C$2:$C$65,AQ$3) -> 0 | ... BX11: =COUNTIFS($A$2:$A$65,$AI11,$C$2:$C$65,BX$3) -> 0 | BY11: =SUM(AJ11:BX11) -> 3 | CC11: 59 | CD11: =$DS11*CD$47/$DS$47 -> 0.03125 | CE11: =$DS11*CE$47/$DS$47 -> 0.03125 | CF11: =$DS11*CF$47/$DS$47 -> 0.03125 | CG11: =$DS11*CG$47/$DS$47 -> 0.0625 | CH11: =$DS11*CH$47/$DS$47 -> 0.0625 | CI11: =$DS11*CI$47/$DS$47 -> 0.0625 | CJ11: =$DS11*CJ$47/$DS$47 -> 0.03125 | CK11: =$DS11*CK$47/$DS$47 -> 0.09375 | ... DR11: =$DS11*DR$47/$DS$47 -> 0.03125 | DS11: 2
A12: 43 | B12: 15 | C12: 63 | E12: 43 | F12: =COUNTIFS($A$2:$A$65,$E12,$B$2:$B$65,F$3) -> 0 | G12: =COUNTIFS($A$2:$A$65,$E12,$B$2:$B$65,G$3) -> 0 | H12: =COUNTIFS($A$2:$A$65,$E12,$B$2:$B$65,H$3) -> 0 | I12: =COUNTIFS($A$2:$A$65,$E12,$B$2:$B$65,I$3) -> 0 | J12: =COUNTIFS($A$2:$A$65,$E12,$B$2:$B$65,J$3) -> 0 | K12: =COUNTIFS($A$2:$A$65,$E12,$B$2:$B$65,K$3) -> 0 | L12: =COUNTIFS($A$2:$A$65,$E12,$B$2:$B$65,L$3) -> 0 | M12: =COUNTIFS($A$2:$A$65,$E12,$B$2:$B$65,M$3) -> 0 | ... O12: =COUNTIFS($A$2:$A$65,$E12,$B$2:$B$65,O$3) -> 0 | P12: =SUM(F12:O12) -> 0 | S12: 49 | T12: =ROUND($AD12*T$47/$AD$47,3) -> 0.859 | U12: =ROUND($AD12*U$47/$AD$47,3) -> 0.469 | V12: =ROUND($AD12*V$47/$AD$47,3) -> 0.391 | W12: =ROUND($AD12*W$47/$AD$47,3) -> 0.625 | X12: =ROUND($AD12*X$47/$AD$47,3) -> 0.391 | Y12: =ROUND($AD12*Y$47/$AD$47,3) -> 0.391 | Z12: =ROUND($AD12*Z$47/$AD$47,3) -> 0.313 | AA12: =ROUND($AD12*AA$47/$AD$47,3) -> 0.391 | ... AC12: =ROUND($AD12*AC$47/$AD$47,3) -> 0.625 | AD12: 5 | AI12: 49 | AJ12: =COUNTIFS($A$2:$A$65,$AI12,$C$2:$C$65,AJ$3) -> 0 | AK12: =COUNTIFS($A$2:$A$65,$AI12,$C$2:$C$65,AK$3) -> 0 | AL12: =COUNTIFS($A$2:$A$65,$AI12,$C$2:$C$65,AL$3) -> 0 | AM12: =COUNTIFS($A$2:$A$65,$AI12,$C$2:$C$65,AM$3) -> 0 | AN12: =COUNTIFS($A$2:$A$65,$AI12,$C$2:$C$65,AN$3) -> 0 | AO12: =COUNTIFS($A$2:$A$65,$AI12,$C$2:$C$65,AO$3) -> 0 | AP12: =COUNTIFS($A$2:$A$65,$AI12,$C$2:$C$65,AP$3) -> 0 | AQ12: =COUNTIFS($A$2:$A$65,$AI12,$C$2:$C$65,AQ$3) -> 0 | ... BX12: =COUNTIFS($A$2:$A$65,$AI12,$C$2:$C$65,BX$3) -> 0 | BY12: =SUM(AJ12:BX12) -> 1 | CC12: 49 | CD12: =$DS12*CD$47/$DS$47 -> 0.078125 | CE12: =$DS12*CE$47/$DS$47 -> 0.078125 | CF12: =$DS12*CF$47/$DS$47 -> 0.078125 | CG12: =$DS12*CG$47/$DS$47 -> 0.15625 | CH12: =$DS12*CH$47/$DS$47 -> 0.15625 | CI12: =$DS12*CI$47/$DS$47 -> 0.15625 | CJ12: =$DS12*CJ$47/$DS$47 -> 0.078125 | CK12: =$DS12*CK$47/$DS$47 -> 0.234375 | ... DR12: =$DS12*DR$47/$DS$47 -> 0.078125 | DS12: 5
A13: 19 | B13: 13 | C13: 42 | E13: 19 | F13: =COUNTIFS($A$2:$A$65,$E13,$B$2:$B$65,F$3) -> 0 | G13: =COUNTIFS($A$2:$A$65,$E13,$B$2:$B$65,G$3) -> 0 | H13: =COUNTIFS($A$2:$A$65,$E13,$B$2:$B$65,H$3) -> 0 | I13: =COUNTIFS($A$2:$A$65,$E13,$B$2:$B$65,I$3) -> 0 | J13: =COUNTIFS($A$2:$A$65,$E13,$B$2:$B$65,J$3) -> 0 | K13: =COUNTIFS($A$2:$A$65,$E13,$B$2:$B$65,K$3) -> 0 | L13: =COUNTIFS($A$2:$A$65,$E13,$B$2:$B$65,L$3) -> 0 | M13: =COUNTIFS($A$2:$A$65,$E13,$B$2:$B$65,M$3) -> 0 | ... O13: =COUNTIFS($A$2:$A$65,$E13,$B$2:$B$65,O$3) -> 0 | P13: =SUM(F13:O13) -> 0 | S13: 21 | T13: =ROUND($AD13*T$47/$AD$47,3) -> 0.172 | U13: =ROUND($AD13*U$47/$AD$47,3) -> 0.094 | V13: =ROUND($AD13*V$47/$AD$47,3) -> 0.078 | W13: =ROUND($AD13*W$47/$AD$47,3) -> 0.125 | X13: =ROUND($AD13*X$47/$AD$47,3) -> 0.078 | Y13: =ROUND($AD13*Y$47/$AD$47,3) -> 0.078 | Z13: =ROUND($AD13*Z$47/$AD$47,3) -> 0.063 | AA13: =ROUND($AD13*AA$47/$AD$47,3) -> 0.078 | ... AC13: =ROUND($AD13*AC$47/$AD$47,3) -> 0.125 | AD13: 1 | AI13: 21 | AJ13: =COUNTIFS($A$2:$A$65,$AI13,$C$2:$C$65,AJ$3) -> 0 | AK13: =COUNTIFS($A$2:$A$65,$AI13,$C$2:$C$65,AK$3) -> 0 | AL13: =COUNTIFS($A$2:$A$65,$AI13,$C$2:$C$65,AL$3) -> 0 | AM13: =COUNTIFS($A$2:$A$65,$AI13,$C$2:$C$65,AM$3) -> 0 | AN13: =COUNTIFS($A$2:$A$65,$AI13,$C$2:$C$65,AN$3) -> 0 | AO13: =COUNTIFS($A$2:$A$65,$AI13,$C$2:$C$65,AO$3) -> 0 | AP13: =COUNTIFS($A$2:$A$65,$AI13,$C$2:$C$65,AP$3) -> 0 | AQ13: =COUNTIFS($A$2:$A$65,$AI13,$C$2:$C$65,AQ$3) -> 0 | ... BX13: =COUNTIFS($A$2:$A$65,$AI13,$C$2:$C$65,BX$3) -> 0 | BY13: =SUM(AJ13:BX13) -> 0 | CC13: 21 | CD13: =$DS13*CD$47/$DS$47 -> 0.015625 | CE13: =$DS13*CE$47/$DS$47 -> 0.015625 | CF13: =$DS13*CF$47/$DS$47 -> 0.015625 | CG13: =$DS13*CG$47/$DS$47 -> 0.03125 | CH13: =$DS13*CH$47/$DS$47 -> 0.03125 | CI13: =$DS13*CI$47/$DS$47 -> 0.03125 | CJ13: =$DS13*CJ$47/$DS$47 -> 0.015625 | CK13: =$DS13*CK$47/$DS$47 -> 0.046875 | ... DR13: =$DS13*DR$47/$DS$47 -> 0.015625 | DS13: 1
A14: 57 | B14: 18 | C14: 30 | E14: 57 | F14: =COUNTIFS($A$2:$A$65,$E14,$B$2:$B$65,F$3) -> 0 | G14: =COUNTIFS($A$2:$A$65,$E14,$B$2:$B$65,G$3) -> 0 | H14: =COUNTIFS($A$2:$A$65,$E14,$B$2:$B$65,H$3) -> 0 | I14: =COUNTIFS($A$2:$A$65,$E14,$B$2:$B$65,I$3) -> 0 | J14: =COUNTIFS($A$2:$A$65,$E14,$B$2:$B$65,J$3) -> 0 | K14: =COUNTIFS($A$2:$A$65,$E14,$B$2:$B$65,K$3) -> 0 | L14: =COUNTIFS($A$2:$A$65,$E14,$B$2:$B$65,L$3) -> 0 | M14: =COUNTIFS($A$2:$A$65,$E14,$B$2:$B$65,M$3) -> 0 | ... O14: =COUNTIFS($A$2:$A$65,$E14,$B$2:$B$65,O$3) -> 0 | P14: =SUM(F14:O14) -> 0 | S14: 33 | T14: =ROUND($AD14*T$47/$AD$47,3) -> 0.172 | U14: =ROUND($AD14*U$47/$AD$47,3) -> 0.094 | V14: =ROUND($AD14*V$47/$AD$47,3) -> 0.078 | W14: =ROUND($AD14*W$47/$AD$47,3) -> 0.125 | X14: =ROUND($AD14*X$47/$AD$47,3) -> 0.078 | Y14: =ROUND($AD14*Y$47/$AD$47,3) -> 0.078 | Z14: =ROUND($AD14*Z$47/$AD$47,3) -> 0.063 | AA14: =ROUND($AD14*AA$47/$AD$47,3) -> 0.078 | ... AC14: =ROUND($AD14*AC$47/$AD$47,3) -> 0.125 | AD14: 1 | AI14: 33 | AJ14: =COUNTIFS($A$2:$A$65,$AI14,$C$2:$C$65,AJ$3) -> 0 | AK14: =COUNTIFS($A$2:$A$65,$AI14,$C$2:$C$65,AK$3) -> 0 | AL14: =COUNTIFS($A$2:$A$65,$AI14,$C$2:$C$65,AL$3) -> 0 | AM14: =COUNTIFS($A$2:$A$65,$AI14,$C$2:$C$65,AM$3) -> 0 | AN14: =COUNTIFS($A$2:$A$65,$AI14,$C$2:$C$65,AN$3) -> 0 | AO14: =COUNTIFS($A$2:$A$65,$AI14,$C$2:$C$65,AO$3) -> 0 | AP14: =COUNTIFS($A$2:$A$65,$AI14,$C$2:$C$65,AP$3) -> 0 | AQ14: =COUNTIFS($A$2:$A$65,$AI14,$C$2:$C$65,AQ$3) -> 0 | ... BX14: =COUNTIFS($A$2:$A$65,$AI14,$C$2:$C$65,BX$3) -> 0 | BY14: =SUM(AJ14:BX14) -> 0 | CC14: 33 | CD14: =$DS14*CD$47/$DS$47 -> 0.015625 | CE14: =$DS14*CE$47/$DS$47 -> 0.015625 | CF14: =$DS14*CF$47/$DS$47 -> 0.015625 | CG14: =$DS14*CG$47/$DS$47 -> 0.03125 | CH14: =$DS14*CH$47/$DS$47 -> 0.03125 | CI14: =$DS14*CI$47/$DS$47 -> 0.03125 | CJ14: =$DS14*CJ$47/$DS$47 -> 0.015625 | CK14: =$DS14*CK$47/$DS$47 -> 0.046875 | ... DR14: =$DS14*DR$47/$DS$47 -> 0.015625 | DS14: 1
A15: 48 | B15: 12 | C15: 75 | E15: 87 | F15: =COUNTIFS($A$2:$A$65,$E15,$B$2:$B$65,F$3) -> 0 | G15: =COUNTIFS($A$2:$A$65,$E15,$B$2:$B$65,G$3) -> 1 | H15: =COUNTIFS($A$2:$A$65,$E15,$B$2:$B$65,H$3) -> 0 | I15: =COUNTIFS($A$2:$A$65,$E15,$B$2:$B$65,I$3) -> 0 | J15: =COUNTIFS($A$2:$A$65,$E15,$B$2:$B$65,J$3) -> 0 | K15: =COUNTIFS($A$2:$A$65,$E15,$B$2:$B$65,K$3) -> 0 | L15: =COUNTIFS($A$2:$A$65,$E15,$B$2:$B$65,L$3) -> 1 | M15: =COUNTIFS($A$2:$A$65,$E15,$B$2:$B$65,M$3) -> 0 | ... O15: =COUNTIFS($A$2:$A$65,$E15,$B$2:$B$65,O$3) -> 0 | P15: =SUM(F15:O15) -> 2 | S15: 39 | T15: =ROUND($AD15*T$47/$AD$47,3) -> 0.516 | U15: =ROUND($AD15*U$47/$AD$47,3) -> 0.281 | V15: =ROUND($AD15*V$47/$AD$47,3) -> 0.234 | W15: =ROUND($AD15*W$47/$AD$47,3) -> 0.375 | X15: =ROUND($AD15*X$47/$AD$47,3) -> 0.234 | Y15: =ROUND($AD15*Y$47/$AD$47,3) -> 0.234 | Z15: =ROUND($AD15*Z$47/$AD$47,3) -> 0.188 | AA15: =ROUND($AD15*AA$47/$AD$47,3) -> 0.234 | ... AC15: =ROUND($AD15*AC$47/$AD$47,3) -> 0.375 | AD15: 3 | AI15: 39 | AJ15: =COUNTIFS($A$2:$A$65,$AI15,$C$2:$C$65,AJ$3) -> 0 | AK15: =COUNTIFS($A$2:$A$65,$AI15,$C$2:$C$65,AK$3) -> 0 | AL15: =COUNTIFS($A$2:$A$65,$AI15,$C$2:$C$65,AL$3) -> 0 | AM15: =COUNTIFS($A$2:$A$65,$AI15,$C$2:$C$65,AM$3) -> 0 | AN15: =COUNTIFS($A$2:$A$65,$AI15,$C$2:$C$65,AN$3) -> 0 | AO15: =COUNTIFS($A$2:$A$65,$AI15,$C$2:$C$65,AO$3) -> 0 | AP15: =COUNTIFS($A$2:$A$65,$AI15,$C$2:$C$65,AP$3) -> 0 | AQ15: =COUNTIFS($A$2:$A$65,$AI15,$C$2:$C$65,AQ$3) -> 0 | ... BX15: =COUNTIFS($A$2:$A$65,$AI15,$C$2:$C$65,BX$3) -> 0 | BY15: =SUM(AJ15:BX15) -> 1 | CC15: 39 | CD15: =$DS15*CD$47/$DS$47 -> 0.046875 | CE15: =$DS15*CE$47/$DS$47 -> 0.046875 | CF15: =$DS15*CF$47/$DS$47 -> 0.046875 | CG15: =$DS15*CG$47/$DS$47 -> 0.09375 | CH15: =$DS15*CH$47/$DS$47 -> 0.09375 | CI15: =$DS15*CI$47/$DS$47 -> 0.09375 | CJ15: =$DS15*CJ$47/$DS$47 -> 0.046875 | CK15: =$DS15*CK$47/$DS$47 -> 0.140625 | ... DR15: =$DS15*DR$47/$DS$47 -> 0.046875 | DS15: 3
A16: 55 | B16: 15 | C16: 78 | E16: 37 | F16: =COUNTIFS($A$2:$A$65,$E16,$B$2:$B$65,F$3) -> 0 | G16: =COUNTIFS($A$2:$A$65,$E16,$B$2:$B$65,G$3) -> 0 | H16: =COUNTIFS($A$2:$A$65,$E16,$B$2:$B$65,H$3) -> 0 | I16: =COUNTIFS($A$2:$A$65,$E16,$B$2:$B$65,I$3) -> 0 | J16: =COUNTIFS($A$2:$A$65,$E16,$B$2:$B$65,J$3) -> 0 | K16: =COUNTIFS($A$2:$A$65,$E16,$B$2:$B$65,K$3) -> 0 | L16: =COUNTIFS($A$2:$A$65,$E16,$B$2:$B$65,L$3) -> 1 | M16: =COUNTIFS($A$2:$A$65,$E16,$B$2:$B$65,M$3) -> 0 | ... O16: =COUNTIFS($A$2:$A$65,$E16,$B$2:$B$65,O$3) -> 0 | P16: =SUM(F16:O16) -> 1 | S16: 64 | T16: =ROUND($AD16*T$47/$AD$47,3) -> 0.172 | U16: =ROUND($AD16*U$47/$AD$47,3) -> 0.094 | V16: =ROUND($AD16*V$47/$AD$47,3) -> 0.078 | W16: =ROUND($AD16*W$47/$AD$47,3) -> 0.125 | X16: =ROUND($AD16*X$47/$AD$47,3) -> 0.078 | Y16: =ROUND($AD16*Y$47/$AD$47,3) -> 0.078 | Z16: =ROUND($AD16*Z$47/$AD$47,3) -> 0.063 | AA16: =ROUND($AD16*AA$47/$AD$47,3) -> 0.078 | ... AC16: =ROUND($AD16*AC$47/$AD$47,3) -> 0.125 | AD16: 1 | AI16: 64 | AJ16: =COUNTIFS($A$2:$A$65,$AI16,$C$2:$C$65,AJ$3) -> 0 | AK16: =COUNTIFS($A$2:$A$65,$AI16,$C$2:$C$65,AK$3) -> 0 | AL16: =COUNTIFS($A$2:$A$65,$AI16,$C$2:$C$65,AL$3) -> 0 | AM16: =COUNTIFS($A$2:$A$65,$AI16,$C$2:$C$65,AM$3) -> 0 | AN16: =COUNTIFS($A$2:$A$65,$AI16,$C$2:$C$65,AN$3) -> 0 | AO16: =COUNTIFS($A$2:$A$65,$AI16,$C$2:$C$65,AO$3) -> 0 | AP16: =COUNTIFS($A$2:$A$65,$AI16,$C$2:$C$65,AP$3) -> 0 | AQ16: =COUNTIFS($A$2:$A$65,$AI16,$C$2:$C$65,AQ$3) -> 0 | ... BX16: =COUNTIFS($A$2:$A$65,$AI16,$C$2:$C$65,BX$3) -> 0 | BY16: =SUM(AJ16:BX16) -> 0 | CC16: 64 | CD16: =$DS16*CD$47/$DS$47 -> 0.015625 | CE16: =$DS16*CE$47/$DS$47 -> 0.015625 | CF16: =$DS16*CF$47/$DS$47 -> 0.015625 | CG16: =$DS16*CG$47/$DS$47 -> 0.03125 | CH16: =$DS16*CH$47/$DS$47 -> 0.03125 | CI16: =$DS16*CI$47/$DS$47 -> 0.03125 | CJ16: =$DS16*CJ$47/$DS$47 -> 0.015625 | CK16: =$DS16*CK$47/$DS$47 -> 0.046875 | ... DR16: =$DS16*DR$47/$DS$47 -> 0.015625 | DS16: 1
A17: 87 | B17: 7 | C17: 53 | E17: 49 | F17: =COUNTIFS($A$2:$A$65,$E17,$B$2:$B$65,F$3) -> 0 | G17: =COUNTIFS($A$2:$A$65,$E17,$B$2:$B$65,G$3) -> 0 | H17: =COUNTIFS($A$2:$A$65,$E17,$B$2:$B$65,H$3) -> 0 | I17: =COUNTIFS($A$2:$A$65,$E17,$B$2:$B$65,I$3) -> 0 | J17: =COUNTIFS($A$2:$A$65,$E17,$B$2:$B$65,J$3) -> 0 | K17: =COUNTIFS($A$2:$A$65,$E17,$B$2:$B$65,K$3) -> 0 | L17: =COUNTIFS($A$2:$A$65,$E17,$B$2:$B$65,L$3) -> 0 | M17: =COUNTIFS($A$2:$A$65,$E17,$B$2:$B$65,M$3) -> 0 | ... O17: =COUNTIFS($A$2:$A$65,$E17,$B$2:$B$65,O$3) -> 0 | P17: =SUM(F17:O17) -> 0 | S17: 74 | T17: =ROUND($AD17*T$47/$AD$47,3) -> 0.172 | U17: =ROUND($AD17*U$47/$AD$47,3) -> 0.094 | V17: =ROUND($AD17*V$47/$AD$47,3) -> 0.078 | W17: =ROUND($AD17*W$47/$AD$47,3) -> 0.125 | X17: =ROUND($AD17*X$47/$AD$47,3) -> 0.078 | Y17: =ROUND($AD17*Y$47/$AD$47,3) -> 0.078 | Z17: =ROUND($AD17*Z$47/$AD$47,3) -> 0.063 | AA17: =ROUND($AD17*AA$47/$AD$47,3) -> 0.078 | ... AC17: =ROUND($AD17*AC$47/$AD$47,3) -> 0.125 | AD17: 1 | AI17: 74 | AJ17: =COUNTIFS($A$2:$A$65,$AI17,$C$2:$C$65,AJ$3) -> 0 | AK17: =COUNTIFS($A$2:$A$65,$AI17,$C$2:$C$65,AK$3) -> 0 | AL17: =COUNTIFS($A$2:$A$65,$AI17,$C$2:$C$65,AL$3) -> 0 | AM17: =COUNTIFS($A$2:$A$65,$AI17,$C$2:$C$65,AM$3) -> 0 | AN17: =COUNTIFS($A$2:$A$65,$AI17,$C$2:$C$65,AN$3) -> 0 | AO17: =COUNTIFS($A$2:$A$65,$AI17,$C$2:$C$65,AO$3) -> 0 | AP17: =COUNTIFS($A$2:$A$65,$AI17,$C$2:$C$65,AP$3) -> 0 | AQ17: =COUNTIFS($A$2:$A$65,$AI17,$C$2:$C$65,AQ$3) -> 0 | ... BX17: =COUNTIFS($A$2:$A$65,$AI17,$C$2:$C$65,BX$3) -> 0 | BY17: =SUM(AJ17:BX17) -> 0 | CC17: 74 | CD17: =$DS17*CD$47/$DS$47 -> 0.015625 | CE17: =$DS17*CE$47/$DS$47 -> 0.015625 | CF17: =$DS17*CF$47/$DS$47 -> 0.015625 | CG17: =$DS17*CG$47/$DS$47 -> 0.03125 | CH17: =$DS17*CH$47/$DS$47 -> 0.03125 | CI17: =$DS17*CI$47/$DS$47 -> 0.03125 | CJ17: =$DS17*CJ$47/$DS$47 -> 0.015625 | CK17: =$DS17*CK$47/$DS$47 -> 0.046875 | ... DR17: =$DS17*DR$47/$DS$47 -> 0.015625 | DS17: 1
A18: 55 | B18: 15 | C18: 71 | E18: 50 | F18: =COUNTIFS($A$2:$A$65,$E18,$B$2:$B$65,F$3) -> 1 | G18: =COUNTIFS($A$2:$A$65,$E18,$B$2:$B$65,G$3) -> 0 | H18: =COUNTIFS($A$2:$A$65,$E18,$B$2:$B$65,H$3) -> 0 | I18: =COUNTIFS($A$2:$A$65,$E18,$B$2:$B$65,I$3) -> 1 | J18: =COUNTIFS($A$2:$A$65,$E18,$B$2:$B$65,J$3) -> 0 | K18: =COUNTIFS($A$2:$A$65,$E18,$B$2:$B$65,K$3) -> 0 | L18: =COUNTIFS($A$2:$A$65,$E18,$B$2:$B$65,L$3) -> 0 | M18: =COUNTIFS($A$2:$A$65,$E18,$B$2:$B$65,M$3) -> 0 | ... O18: =COUNTIFS($A$2:$A$65,$E18,$B$2:$B$65,O$3) -> 0 | P18: =SUM(F18:O18) -> 2 | S18: 56 | T18: =ROUND($AD18*T$47/$AD$47,3) -> 0.344 | U18: =ROUND($AD18*U$47/$AD$47,3) -> 0.188 | V18: =ROUND($AD18*V$47/$AD$47,3) -> 0.156 | W18: =ROUND($AD18*W$47/$AD$47,3) -> 0.25 | X18: =ROUND($AD18*X$47/$AD$47,3) -> 0.156 | Y18: =ROUND($AD18*Y$47/$AD$47,3) -> 0.156 | Z18: =ROUND($AD18*Z$47/$AD$47,3) -> 0.125 | AA18: =ROUND($AD18*AA$47/$AD$47,3) -> 0.156 | ... AC18: =ROUND($AD18*AC$47/$AD$47,3) -> 0.25 | AD18: 2 | AI18: 56 | AJ18: =COUNTIFS($A$2:$A$65,$AI18,$C$2:$C$65,AJ$3) -> 0 | AK18: =COUNTIFS($A$2:$A$65,$AI18,$C$2:$C$65,AK$3) -> 0 | AL18: =COUNTIFS($A$2:$A$65,$AI18,$C$2:$C$65,AL$3) -> 0 | AM18: =COUNTIFS($A$2:$A$65,$AI18,$C$2:$C$65,AM$3) -> 0 | AN18: =COUNTIFS($A$2:$A$65,$AI18,$C$2:$C$65,AN$3) -> 0 | AO18: =COUNTIFS($A$2:$A$65,$AI18,$C$2:$C$65,AO$3) -> 0 | AP18: =COUNTIFS($A$2:$A$65,$AI18,$C$2:$C$65,AP$3) -> 0 | AQ18: =COUNTIFS($A$2:$A$65,$AI18,$C$2:$C$65,AQ$3) -> 0 | ... BX18: =COUNTIFS($A$2:$A$65,$AI18,$C$2:$C$65,BX$3) -> 0 | BY18: =SUM(AJ18:BX18) -> 0 | CC18: 56 | CD18: =$DS18*CD$47/$DS$47 -> 0.03125 | CE18: =$DS18*CE$47/$DS$47 -> 0.03125 | CF18: =$DS18*CF$47/$DS$47 -> 0.03125 | CG18: =$DS18*CG$47/$DS$47 -> 0.0625 | CH18: =$DS18*CH$47/$DS$47 -> 0.0625 | CI18: =$DS18*CI$47/$DS$47 -> 0.0625 | CJ18: =$DS18*CJ$47/$DS$47 -> 0.03125 | CK18: =$DS18*CK$47/$DS$47 -> 0.09375 | ... DR18: =$DS18*DR$47/$DS$47 -> 0.03125 | DS18: 2
A19: 37 | B19: 7 | C19: 80 | E19: 38 | F19: =COUNTIFS($A$2:$A$65,$E19,$B$2:$B$65,F$3) -> 0 | G19: =COUNTIFS($A$2:$A$65,$E19,$B$2:$B$65,G$3) -> 0 | H19: =COUNTIFS($A$2:$A$65,$E19,$B$2:$B$65,H$3) -> 0 | I19: =COUNTIFS($A$2:$A$65,$E19,$B$2:$B$65,I$3) -> 0 | J19: =COUNTIFS($A$2:$A$65,$E19,$B$2:$B$65,J$3) -> 0 | K19: =COUNTIFS($A$2:$A$65,$E19,$B$2:$B$65,K$3) -> 0 | L19: =COUNTIFS($A$2:$A$65,$E19,$B$2:$B$65,L$3) -> 0 | M19: =COUNTIFS($A$2:$A$65,$E19,$B$2:$B$65,M$3) -> 0 | ... O19: =COUNTIFS($A$2:$A$65,$E19,$B$2:$B$65,O$3) -> 0 | P19: =SUM(F19:O19) -> 0 | S19: 53 | T19: =ROUND($AD19*T$47/$AD$47,3) -> 0.344 | U19: =ROUND($AD19*U$47/$AD$47,3) -> 0.188 | V19: =ROUND($AD19*V$47/$AD$47,3) -> 0.156 | W19: =ROUND($AD19*W$47/$AD$47,3) -> 0.25 | X19: =ROUND($AD19*X$47/$AD$47,3) -> 0.156 | Y19: =ROUND($AD19*Y$47/$AD$47,3) -> 0.156 | Z19: =ROUND($AD19*Z$47/$AD$47,3) -> 0.125 | AA19: =ROUND($AD19*AA$47/$AD$47,3) -> 0.156 | ... AC19: =ROUND($AD19*AC$47/$AD$47,3) -> 0.25 | AD19: 2 | AI19: 53 | AJ19: =COUNTIFS($A$2:$A$65,$AI19,$C$2:$C$65,AJ$3) -> 0 | AK19: =COUNTIFS($A$2:$A$65,$AI19,$C$2:$C$65,AK$3) -> 0 | AL19: =COUNTIFS($A$2:$A$65,$AI19,$C$2:$C$65,AL$3) -> 0 | AM19: =COUNTIFS($A$2:$A$65,$AI19,$C$2:$C$65,AM$3) -> 0 | AN19: =COUNTIFS($A$2:$A$65,$AI19,$C$2:$C$65,AN$3) -> 0 | AO19: =COUNTIFS($A$2:$A$65,$AI19,$C$2:$C$65,AO$3) -> 0 | AP19: =COUNTIFS($A$2:$A$65,$AI19,$C$2:$C$65,AP$3) -> 0 | AQ19: =COUNTIFS($A$2:$A$65,$AI19,$C$2:$C$65,AQ$3) -> 0 | ... BX19: =COUNTIFS($A$2:$A$65,$AI19,$C$2:$C$65,BX$3) -> 0 | BY19: =SUM(AJ19:BX19) -> 0 | CC19: 53 | CD19: =$DS19*CD$47/$DS$47 -> 0.03125 | CE19: =$DS19*CE$47/$DS$47 -> 0.03125 | CF19: =$DS19*CF$47/$DS$47 -> 0.03125 | CG19: =$DS19*CG$47/$DS$47 -> 0.0625 | CH19: =$DS19*CH$47/$DS$47 -> 0.0625 | CI19: =$DS19*CI$47/$DS$47 -> 0.0625 | CJ19: =$DS19*CJ$47/$DS$47 -> 0.03125 | CK19: =$DS19*CK$47/$DS$47 -> 0.09375 | ... DR19: =$DS19*DR$47/$DS$47 -> 0.03125 | DS19: 2
A20: 49 | B20: 19 | C20: 30 | E20: 23 | F20: =COUNTIFS($A$2:$A$65,$E20,$B$2:$B$65,F$3) -> 0 | G20: =COUNTIFS($A$2:$A$65,$E20,$B$2:$B$65,G$3) -> 1 | H20: =COUNTIFS($A$2:$A$65,$E20,$B$2:$B$65,H$3) -> 0 | I20: =COUNTIFS($A$2:$A$65,$E20,$B$2:$B$65,I$3) -> 0 | J20: =COUNTIFS($A$2:$A$65,$E20,$B$2:$B$65,J$3) -> 0 | K20: =COUNTIFS($A$2:$A$65,$E20,$B$2:$B$65,K$3) -> 0 | L20: =COUNTIFS($A$2:$A$65,$E20,$B$2:$B$65,L$3) -> 0 | M20: =COUNTIFS($A$2:$A$65,$E20,$B$2:$B$65,M$3) -> 0 | ... O20: =COUNTIFS($A$2:$A$65,$E20,$B$2:$B$65,O$3) -> 0 | P20: =SUM(F20:O20) -> 1 | S20: 71 | T20: =ROUND($AD20*T$47/$AD$47,3) -> 0.172 | U20: =ROUND($AD20*U$47/$AD$47,3) -> 0.094 | V20: =ROUND($AD20*V$47/$AD$47,3) -> 0.078 | W20: =ROUND($AD20*W$47/$AD$47,3) -> 0.125 | X20: =ROUND($AD20*X$47/$AD$47,3) -> 0.078 | Y20: =ROUND($AD20*Y$47/$AD$47,3) -> 0.078 | Z20: =ROUND($AD20*Z$47/$AD$47,3) -> 0.063 | AA20: =ROUND($AD20*AA$47/$AD$47,3) -> 0.078 | ... AC20: =ROUND($AD20*AC$47/$AD$47,3) -> 0.125 | AD20: 1 | AI20: 71 | AJ20: =COUNTIFS($A$2:$A$65,$AI20,$C$2:$C$65,AJ$3) -> 0 | AK20: =COUNTIFS($A$2:$A$65,$AI20,$C$2:$C$65,AK$3) -> 0 | AL20: =COUNTIFS($A$2:$A$65,$AI20,$C$2:$C$65,AL$3) -> 0 | AM20: =COUNTIFS($A$2:$A$65,$AI20,$C$2:$C$65,AM$3) -> 0 | AN20: =COUNTIFS($A$2:$A$65,$AI20,$C$2:$C$65,AN$3) -> 0 | AO20: =COUNTIFS($A$2:$A$65,$AI20,$C$2:$C$65,AO$3) -> 0 | AP20: =COUNTIFS($A$2:$A$65,$AI20,$C$2:$C$65,AP$3) -> 0 | AQ20: =COUNTIFS($A$2:$A$65,$AI20,$C$2:$C$65,AQ$3) -> 0 | ... BX20: =COUNTIFS($A$2:$A$65,$AI20,$C$2:$C$65,BX$3) -> 0 | BY20: =SUM(AJ20:BX20) -> 1 | CC20: 71 | CD20: =$DS20*CD$47/$DS$47 -> 0.015625 | CE20: =$DS20*CE$47/$DS$47 -> 0.015625 | CF20: =$DS20*CF$47/$DS$47 -> 0.015625 | CG20: =$DS20*CG$47/$DS$47 -> 0.03125 | CH20: =$DS20*CH$47/$DS$47 -> 0.03125 | CI20: =$DS20*CI$47/$DS$47 -> 0.03125 | CJ20: =$DS20*CJ$47/$DS$47 -> 0.015625 | CK20: =$DS20*CK$47/$DS$47 -> 0.046875 | ... DR20: =$DS20*DR$47/$DS$47 -> 0.015625 | DS20: 1
A21: 55 | B21: 15 | C21: 74 | E21: 60 | F21: =COUNTIFS($A$2:$A$65,$E21,$B$2:$B$65,F$3) -> 0 | G21: =COUNTIFS($A$2:$A$65,$E21,$B$2:$B$65,G$3) -> 0 | H21: =COUNTIFS($A$2:$A$65,$E21,$B$2:$B$65,H$3) -> 0 | I21: =COUNTIFS($A$2:$A$65,$E21,$B$2:$B$65,I$3) -> 0 | J21: =COUNTIFS($A$2:$A$65,$E21,$B$2:$B$65,J$3) -> 1 | K21: =COUNTIFS($A$2:$A$65,$E21,$B$2:$B$65,K$3) -> 0 | L21: =COUNTIFS($A$2:$A$65,$E21,$B$2:$B$65,L$3) -> 0 | M21: =COUNTIFS($A$2:$A$65,$E21,$B$2:$B$65,M$3) -> 0 | ... O21: =COUNTIFS($A$2:$A$65,$E21,$B$2:$B$65,O$3) -> 0 | P21: =SUM(F21:O21) -> 1 | S21: 23 | T21: =ROUND($AD21*T$47/$AD$47,3) -> 0.172 | U21: =ROUND($AD21*U$47/$AD$47,3) -> 0.094 | V21: =ROUND($AD21*V$47/$AD$47,3) -> 0.078 | W21: =ROUND($AD21*W$47/$AD$47,3) -> 0.125 | X21: =ROUND($AD21*X$47/$AD$47,3) -> 0.078 | Y21: =ROUND($AD21*Y$47/$AD$47,3) -> 0.078 | Z21: =ROUND($AD21*Z$47/$AD$47,3) -> 0.063 | AA21: =ROUND($AD21*AA$47/$AD$47,3) -> 0.078 | ... AC21: =ROUND($AD21*AC$47/$AD$47,3) -> 0.125 | AD21: 1 | AI21: 23 | AJ21: =COUNTIFS($A$2:$A$65,$AI21,$C$2:$C$65,AJ$3) -> 0 | AK21: =COUNTIFS($A$2:$A$65,$AI21,$C$2:$C$65,AK$3) -> 0 | AL21: =COUNTIFS($A$2:$A$65,$AI21,$C$2:$C$65,AL$3) -> 0 | AM21: =COUNTIFS($A$2:$A$65,$AI21,$C$2:$C$65,AM$3) -> 0 | AN21: =COUNTIFS($A$2:$A$65,$AI21,$C$2:$C$65,AN$3) -> 0 | AO21: =COUNTIFS($A$2:$A$65,$AI21,$C$2:$C$65,AO$3) -> 1 | AP21: =COUNTIFS($A$2:$A$65,$AI21,$C$2:$C$65,AP$3) -> 0 | AQ21: =COUNTIFS($A$2:$A$65,$AI21,$C$2:$C$65,AQ$3) -> 0 | ... BX21: =COUNTIFS($A$2:$A$65,$AI21,$C$2:$C$65,BX$3) -> 0 | BY21: =SUM(AJ21:BX21) -> 1 | CC21: 23 | CD21: =$DS21*CD$47/$DS$47 -> 0.015625 | CE21: =$DS21*CE$47/$DS$47 -> 0.015625 | CF21: =$DS21*CF$47/$DS$47 -> 0.015625 | CG21: =$DS21*CG$47/$DS$47 -> 0.03125 | CH21: =$DS21*CH$47/$DS$47 -> 0.03125 | CI21: =$DS21*CI$47/$DS$47 -> 0.03125 | CJ21: =$DS21*CJ$47/$DS$47 -> 0.015625 | CK21: =$DS21*CK$47/$DS$47 -> 0.046875 | ... DR21: =$DS21*DR$47/$DS$47 -> 0.015625 | DS21: 1
... A41: 59 | B41: 2 | C41: 64 | E41: 29 | F41: =COUNTIFS($A$2:$A$65,$E41,$B$2:$B$65,F$3) -> 0 | G41: =COUNTIFS($A$2:$A$65,$E41,$B$2:$B$65,G$3) -> 0 | H41: =COUNTIFS($A$2:$A$65,$E41,$B$2:$B$65,H$3) -> 0 | I41: =COUNTIFS($A$2:$A$65,$E41,$B$2:$B$65,I$3) -> 0 | J41: =COUNTIFS($A$2:$A$65,$E41,$B$2:$B$65,J$3) -> 0 | K41: =COUNTIFS($A$2:$A$65,$E41,$B$2:$B$65,K$3) -> 0 | L41: =COUNTIFS($A$2:$A$65,$E41,$B$2:$B$65,L$3) -> 0 | M41: =COUNTIFS($A$2:$A$65,$E41,$B$2:$B$65,M$3) -> 0 | ... O41: =COUNTIFS($A$2:$A$65,$E41,$B$2:$B$65,O$3) -> 0 | P41: =SUM(F41:O41) -> 0 | S41: 54 | T41: =ROUND($AD41*T$47/$AD$47,3) -> 0.172 | U41: =ROUND($AD41*U$47/$AD$47,3) -> 0.094 | V41: =ROUND($AD41*V$47/$AD$47,3) -> 0.078 | W41: =ROUND($AD41*W$47/$AD$47,3) -> 0.125 | X41: =ROUND($AD41*X$47/$AD$47,3) -> 0.078 | Y41: =ROUND($AD41*Y$47/$AD$47,3) -> 0.078 | Z41: =ROUND($AD41*Z$47/$AD$47,3) -> 0.063 | AA41: =ROUND($AD41*AA$47/$AD$47,3) -> 0.078 | ... AC41: =ROUND($AD41*AC$47/$AD$47,3) -> 0.125 | AD41: 1 | AI41: 54 | AJ41: =COUNTIFS($A$2:$A$65,$AI41,$C$2:$C$65,AJ$3) -> 0 | AK41: =COUNTIFS($A$2:$A$65,$AI41,$C$2:$C$65,AK$3) -> 0 | AL41: =COUNTIFS($A$2:$A$65,$AI41,$C$2:$C$65,AL$3) -> 0 | AM41: =COUNTIFS($A$2:$A$65,$AI41,$C$2:$C$65,AM$3) -> 0 | AN41: =COUNTIFS($A$2:$A$65,$AI41,$C$2:$C$65,AN$3) -> 0 | AO41: =COUNTIFS($A$2:$A$65,$AI41,$C$2:$C$65,AO$3) -> 0 | AP41: =COUNTIFS($A$2:$A$65,$AI41,$C$2:$C$65,AP$3) -> 0 | AQ41: =COUNTIFS($A$2:$A$65,$AI41,$C$2:$C$65,AQ$3) -> 0 | ... BX41: =COUNTIFS($A$2:$A$65,$AI41,$C$2:$C$65,BX$3) -> 0 | BY41: =SUM(AJ41:BX41) -> 0 | CC41: 54 | CD41: =$DS41*CD$47/$DS$47 -> 0.015625 | CE41: =$DS41*CE$47/$DS$47 -> 0.015625 | CF41: =$DS41*CF$47/$DS$47 -> 0.015625 | CG41: =$DS41*CG$47/$DS$47 -> 0.03125 | CH41: =$DS41*CH$47/$DS$47 -> 0.03125 | CI41: =$DS41*CI$47/$DS$47 -> 0.03125 | CJ41: =$DS41*CJ$47/$DS$47 -> 0.015625 | CK41: =$DS41*CK$47/$DS$47 -> 0.046875 | ... DR41: =$DS41*DR$47/$DS$47 -> 0.015625 | DS41: 1
A42: 59 | B42: 9 | C42: 32 | F42: =COUNTIFS($A$2:$A$65,$E42,$B$2:$B$65,F$3) -> 0 | G42: =COUNTIFS($A$2:$A$65,$E42,$B$2:$B$65,G$3) -> 0 | H42: =COUNTIFS($A$2:$A$65,$E42,$B$2:$B$65,H$3) -> 0 | I42: =COUNTIFS($A$2:$A$65,$E42,$B$2:$B$65,I$3) -> 0 | J42: =COUNTIFS($A$2:$A$65,$E42,$B$2:$B$65,J$3) -> 0 | K42: =COUNTIFS($A$2:$A$65,$E42,$B$2:$B$65,K$3) -> 0 | L42: =COUNTIFS($A$2:$A$65,$E42,$B$2:$B$65,L$3) -> 0 | M42: =COUNTIFS($A$2:$A$65,$E42,$B$2:$B$65,M$3) -> 0 | ... O42: =COUNTIFS($A$2:$A$65,$E42,$B$2:$B$65,O$3) -> 0 | P42: =SUM(F42:O42) -> 0 | S42: 40 | T42: =ROUND($AD42*T$47/$AD$47,3) -> 0.172 | U42: =ROUND($AD42*U$47/$AD$47,3) -> 0.094 | V42: =ROUND($AD42*V$47/$AD$47,3) -> 0.078 | W42: =ROUND($AD42*W$47/$AD$47,3) -> 0.125 | X42: =ROUND($AD42*X$47/$AD$47,3) -> 0.078 | Y42: =ROUND($AD42*Y$47/$AD$47,3) -> 0.078 | Z42: =ROUND($AD42*Z$47/$AD$47,3) -> 0.063 | AA42: =ROUND($AD42*AA$47/$AD$47,3) -> 0.078 | ... AC42: =ROUND($AD42*AC$47/$AD$47,3) -> 0.125 | AD42: 1 | AI42: 40 | AJ42: =COUNTIFS($A$2:$A$65,$AI42,$C$2:$C$65,AJ$3) -> 0 | AK42: =COUNTIFS($A$2:$A$65,$AI42,$C$2:$C$65,AK$3) -> 0 | AL42: =COUNTIFS($A$2:$A$65,$AI42,$C$2:$C$65,AL$3) -> 0 | AM42: =COUNTIFS($A$2:$A$65,$AI42,$C$2:$C$65,AM$3) -> 0 | AN42: =COUNTIFS($A$2:$A$65,$AI42,$C$2:$C$65,AN$3) -> 0 | AO42: =COUNTIFS($A$2:$A$65,$AI42,$C$2:$C$65,AO$3) -> 0 | AP42: =COUNTIFS($A$2:$A$65,$AI42,$C$2:$C$65,AP$3) -> 0 | AQ42: =COUNTIFS($A$2:$A$65,$AI42,$C$2:$C$65,AQ$3) -> 0 | ... BX42: =COUNTIFS($A$2:$A$65,$AI42,$C$2:$C$65,BX$3) -> 0 | BY42: =SUM(AJ42:BX42) -> 0 | CC42: 40 | CD42: =$DS42*CD$47/$DS$47 -> 0.015625 | CE42: =$DS42*CE$47/$DS$47 -> 0.015625 | CF42: =$DS42*CF$47/$DS$47 -> 0.015625 | CG42: =$DS42*CG$47/$DS$47 -> 0.03125 | CH42: =$DS42*CH$47/$DS$47 -> 0.03125 | CI42: =$DS42*CI$47/$DS$47 -> 0.03125 | CJ42: =$DS42*CJ$47/$DS$47 -> 0.015625 | CK42: =$DS42*CK$47/$DS$47 -> 0.046875 | ... DR42: =$DS42*DR$47/$DS$47 -> 0.015625 | DS42: 1
A43: 41 | B43: 19 | C43: 39 | F43: =COUNTIFS($A$2:$A$65,$E43,$B$2:$B$65,F$3) -> 0 | G43: =COUNTIFS($A$2:$A$65,$E43,$B$2:$B$65,G$3) -> 0 | H43: =COUNTIFS($A$2:$A$65,$E43,$B$2:$B$65,H$3) -> 0 | I43: =COUNTIFS($A$2:$A$65,$E43,$B$2:$B$65,I$3) -> 0 | J43: =COUNTIFS($A$2:$A$65,$E43,$B$2:$B$65,J$3) -> 0 | K43: =COUNTIFS($A$2:$A$65,$E43,$B$2:$B$65,K$3) -> 0 | L43: =COUNTIFS($A$2:$A$65,$E43,$B$2:$B$65,L$3) -> 0 | M43: =COUNTIFS($A$2:$A$65,$E43,$B$2:$B$65,M$3) -> 0 | ... O43: =COUNTIFS($A$2:$A$65,$E43,$B$2:$B$65,O$3) -> 0 | P43: =SUM(F43:O43) -> 0 | S43: 30 | T43: =ROUND($AD43*T$47/$AD$47,3) -> 0.172 | U43: =ROUND($AD43*U$47/$AD$47,3) -> 0.094 | V43: =ROUND($AD43*V$47/$AD$47,3) -> 0.078 | W43: =ROUND($AD43*W$47/$AD$47,3) -> 0.125 | X43: =ROUND($AD43*X$47/$AD$47,3) -> 0.078 | Y43: =ROUND($AD43*Y$47/$AD$47,3) -> 0.078 | Z43: =ROUND($AD43*Z$47/$AD$47,3) -> 0.063 | AA43: =ROUND($AD43*AA$47/$AD$47,3) -> 0.078 | ... AC43: =ROUND($AD43*AC$47/$AD$47,3) -> 0.125 | AD43: 1 | AI43: 30 | AJ43: =COUNTIFS($A$2:$A$65,$AI43,$C$2:$C$65,AJ$3) -> 0 | AK43: =COUNTIFS($A$2:$A$65,$AI43,$C$2:$C$65,AK$3) -> 0 | AL43: =COUNTIFS($A$2:$A$65,$AI43,$C$2:$C$65,AL$3) -> 0 | AM43: =COUNTIFS($A$2:$A$65,$AI43,$C$2:$C$65,AM$3) -> 0 | AN43: =COUNTIFS($A$2:$A$65,$AI43,$C$2:$C$65,AN$3) -> 0 | AO43: =COUNTIFS($A$2:$A$65,$AI43,$C$2:$C$65,AO$3) -> 0 | AP43: =COUNTIFS($A$2:$A$65,$AI43,$C$2:$C$65,AP$3) -> 1 | AQ43: =COUNTIFS($A$2:$A$65,$AI43,$C$2:$C$65,AQ$3) -> 0 | ... BX43: =COUNTIFS($A$2:$A$65,$AI43,$C$2:$C$65,BX$3) -> 0 | BY43: =SUM(AJ43:BX43) -> 1 | CC43: 30 | CD43: =$DS43*CD$47/$DS$47 -> 0.015625 | CE43: =$DS43*CE$47/$DS$47 -> 0.015625 | CF43: =$DS43*CF$47/$DS$47 -> 0.015625 | CG43: =$DS43*CG$47/$DS$47 -> 0.03125 | CH43: =$DS43*CH$47/$DS$47 -> 0.03125 | CI43: =$DS43*CI$47/$DS$47 -> 0.03125 | CJ43: =$DS43*CJ$47/$DS$47 -> 0.015625 | CK43: =$DS43*CK$47/$DS$47 -> 0.046875 | ... DR43: =$DS43*DR$47/$DS$47 -> 0.015625 | DS43: 1
A44: 39 | B44: 14 | C44: 38 | F44: =COUNTIFS($A$2:$A$65,$E44,$B$2:$B$65,F$3) -> 0 | G44: =COUNTIFS($A$2:$A$65,$E44,$B$2:$B$65,G$3) -> 0 | H44: =COUNTIFS($A$2:$A$65,$E44,$B$2:$B$65,H$3) -> 0 | I44: =COUNTIFS($A$2:$A$65,$E44,$B$2:$B$65,I$3) -> 0 | J44: =COUNTIFS($A$2:$A$65,$E44,$B$2:$B$65,J$3) -> 0 | K44: =COUNTIFS($A$2:$A$65,$E44,$B$2:$B$65,K$3) -> 0 | L44: =COUNTIFS($A$2:$A$65,$E44,$B$2:$B$65,L$3) -> 0 | M44: =COUNTIFS($A$2:$A$65,$E44,$B$2:$B$65,M$3) -> 0 | ... O44: =COUNTIFS($A$2:$A$65,$E44,$B$2:$B$65,O$3) -> 0 | P44: =SUM(F44:O44) -> 0 | S44: 73 | T44: =ROUND($AD44*T$47/$AD$47,3) -> 0.172 | U44: =ROUND($AD44*U$47/$AD$47,3) -> 0.094 | V44: =ROUND($AD44*V$47/$AD$47,3) -> 0.078 | W44: =ROUND($AD44*W$47/$AD$47,3) -> 0.125 | X44: =ROUND($AD44*X$47/$AD$47,3) -> 0.078 | Y44: =ROUND($AD44*Y$47/$AD$47,3) -> 0.078 | Z44: =ROUND($AD44*Z$47/$AD$47,3) -> 0.063 | AA44: =ROUND($AD44*AA$47/$AD$47,3) -> 0.078 | ... AC44: =ROUND($AD44*AC$47/$AD$47,3) -> 0.125 | AD44: 1 | AI44: 73 | AJ44: =COUNTIFS($A$2:$A$65,$AI44,$C$2:$C$65,AJ$3) -> 0 | AK44: =COUNTIFS($A$2:$A$65,$AI44,$C$2:$C$65,AK$3) -> 0 | AL44: =COUNTIFS($A$2:$A$65,$AI44,$C$2:$C$65,AL$3) -> 1 | AM44: =COUNTIFS($A$2:$A$65,$AI44,$C$2:$C$65,AM$3) -> 0 | AN44: =COUNTIFS($A$2:$A$65,$AI44,$C$2:$C$65,AN$3) -> 0 | AO44: =COUNTIFS($A$2:$A$65,$AI44,$C$2:$C$65,AO$3) -> 0 | AP44: =COUNTIFS($A$2:$A$65,$AI44,$C$2:$C$65,AP$3) -> 0 | AQ44: =COUNTIFS($A$2:$A$65,$AI44,$C$2:$C$65,AQ$3) -> 1 | ... BX44: =COUNTIFS($A$2:$A$65,$AI44,$C$2:$C$65,BX$3) -> 0 | BY44: =SUM(AJ44:BX44) -> 3 | CC44: 73 | CD44: =$DS44*CD$47/$DS$47 -> 0.015625 | CE44: =$DS44*CE$47/$DS$47 -> 0.015625 | CF44: =$DS44*CF$47/$DS$47 -> 0.015625 | CG44: =$DS44*CG$47/$DS$47 -> 0.03125 | CH44: =$DS44*CH$47/$DS$47 -> 0.03125 | CI44: =$DS44*CI$47/$DS$47 -> 0.03125 | CJ44: =$DS44*CJ$47/$DS$47 -> 0.015625 | CK44: =$DS44*CK$47/$DS$47 -> 0.046875 | ... DR44: =$DS44*DR$47/$DS$47 -> 0.015625 | DS44: 1
A45: 61 | B45: 16 | C45: 55 | F45: =COUNTIFS($A$2:$A$65,$E45,$B$2:$B$65,F$3) -> 0 | G45: =COUNTIFS($A$2:$A$65,$E45,$B$2:$B$65,G$3) -> 0 | H45: =COUNTIFS($A$2:$A$65,$E45,$B$2:$B$65,H$3) -> 0 | I45: =COUNTIFS($A$2:$A$65,$E45,$B$2:$B$65,I$3) -> 0 | J45: =COUNTIFS($A$2:$A$65,$E45,$B$2:$B$65,J$3) -> 0 | K45: =COUNTIFS($A$2:$A$65,$E45,$B$2:$B$65,K$3) -> 0 | L45: =COUNTIFS($A$2:$A$65,$E45,$B$2:$B$65,L$3) -> 0 | M45: =COUNTIFS($A$2:$A$65,$E45,$B$2:$B$65,M$3) -> 0 | ... O45: =COUNTIFS($A$2:$A$65,$E45,$B$2:$B$65,O$3) -> 0 | P45: =SUM(F45:O45) -> 0 | S45: 28 | T45: =ROUND($AD45*T$47/$AD$47,3) -> 0.172 | U45: =ROUND($AD45*U$47/$AD$47,3) -> 0.094 | V45: =ROUND($AD45*V$47/$AD$47,3) -> 0.078 | W45: =ROUND($AD45*W$47/$AD$47,3) -> 0.125 | X45: =ROUND($AD45*X$47/$AD$47,3) -> 0.078 | Y45: =ROUND($AD45*Y$47/$AD$47,3) -> 0.078 | Z45: =ROUND($AD45*Z$47/$AD$47,3) -> 0.063 | AA45: =ROUND($AD45*AA$47/$AD$47,3) -> 0.078 | ... AC45: =ROUND($AD45*AC$47/$AD$47,3) -> 0.125 | AD45: 1 | AI45: 28 | AJ45: =COUNTIFS($A$2:$A$65,$AI45,$C$2:$C$65,AJ$3) -> 0 | AK45: =COUNTIFS($A$2:$A$65,$AI45,$C$2:$C$65,AK$3) -> 0 | AL45: =COUNTIFS($A$2:$A$65,$AI45,$C$2:$C$65,AL$3) -> 0 | AM45: =COUNTIFS($A$2:$A$65,$AI45,$C$2:$C$65,AM$3) -> 0 | AN45: =COUNTIFS($A$2:$A$65,$AI45,$C$2:$C$65,AN$3) -> 0 | AO45: =COUNTIFS($A$2:$A$65,$AI45,$C$2:$C$65,AO$3) -> 0 | AP45: =COUNTIFS($A$2:$A$65,$AI45,$C$2:$C$65,AP$3) -> 0 | AQ45: =COUNTIFS($A$2:$A$65,$AI45,$C$2:$C$65,AQ$3) -> 0 | ... BX45: =COUNTIFS($A$2:$A$65,$AI45,$C$2:$C$65,BX$3) -> 0 | BY45: =SUM(AJ45:BX45) -> 0 | CC45: 28 | CD45: =$DS45*CD$47/$DS$47 -> 0.015625 | CE45: =$DS45*CE$47/$DS$47 -> 0.015625 | CF45: =$DS45*CF$47/$DS$47 -> 0.015625 | CG45: =$DS45*CG$47/$DS$47 -> 0.03125 | CH45: =$DS45*CH$47/$DS$47 -> 0.03125 | CI45: =$DS45*CI$47/$DS$47 -> 0.03125 | CJ45: =$DS45*CJ$47/$DS$47 -> 0.015625 | CK45: =$DS45*CK$47/$DS$47 -> 0.046875 | ... DR45: =$DS45*DR$47/$DS$47 -> 0.015625 | DS45: 1
A46: 58 | B46: 17 | C46: 61 | F46: =COUNTIFS($A$2:$A$65,$E46,$B$2:$B$65,F$3) -> 0 | G46: =COUNTIFS($A$2:$A$65,$E46,$B$2:$B$65,G$3) -> 0 | H46: =COUNTIFS($A$2:$A$65,$E46,$B$2:$B$65,H$3) -> 0 | I46: =COUNTIFS($A$2:$A$65,$E46,$B$2:$B$65,I$3) -> 0 | J46: =COUNTIFS($A$2:$A$65,$E46,$B$2:$B$65,J$3) -> 0 | K46: =COUNTIFS($A$2:$A$65,$E46,$B$2:$B$65,K$3) -> 0 | L46: =COUNTIFS($A$2:$A$65,$E46,$B$2:$B$65,L$3) -> 0 | M46: =COUNTIFS($A$2:$A$65,$E46,$B$2:$B$65,M$3) -> 0 | ... O46: =COUNTIFS($A$2:$A$65,$E46,$B$2:$B$65,O$3) -> 0 | P46: =SUM(F46:O46) -> 0 | S46: 67 | T46: =ROUND($AD46*T$47/$AD$47,3) -> 0.172 | U46: =ROUND($AD46*U$47/$AD$47,3) -> 0.094 | V46: =ROUND($AD46*V$47/$AD$47,3) -> 0.078 | W46: =ROUND($AD46*W$47/$AD$47,3) -> 0.125 | X46: =ROUND($AD46*X$47/$AD$47,3) -> 0.078 | Y46: =ROUND($AD46*Y$47/$AD$47,3) -> 0.078 | Z46: =ROUND($AD46*Z$47/$AD$47,3) -> 0.063 | AA46: =ROUND($AD46*AA$47/$AD$47,3) -> 0.078 | ... AC46: =ROUND($AD46*AC$47/$AD$47,3) -> 0.125 | AD46: 1 | AI46: 67 | AJ46: =COUNTIFS($A$2:$A$65,$AI46,$C$2:$C$65,AJ$3) -> 0 | AK46: =COUNTIFS($A$2:$A$65,$AI46,$C$2:$C$65,AK$3) -> 0 | AL46: =COUNTIFS($A$2:$A$65,$AI46,$C$2:$C$65,AL$3) -> 0 | AM46: =COUNTIFS($A$2:$A$65,$AI46,$C$2:$C$65,AM$3) -> 0 | AN46: =COUNTIFS($A$2:$A$65,$AI46,$C$2:$C$65,AN$3) -> 0 | AO46: =COUNTIFS($A$2:$A$65,$AI46,$C$2:$C$65,AO$3) -> 0 | AP46: =COUNTIFS($A$2:$A$65,$AI46,$C$2:$C$65,AP$3) -> 0 | AQ46: =COUNTIFS($A$2:$A$65,$AI46,$C$2:$C$65,AQ$3) -> 0 | ... BX46: =COUNTIFS($A$2:$A$65,$AI46,$C$2:$C$65,BX$3) -> 0 | BY46: =SUM(AJ46:BX46) -> 1 | CC46: 67 | CD46: =$DS46*CD$47/$DS$47 -> 0.015625 | CE46: =$DS46*CE$47/$DS$47 -> 0.015625 | CF46: =$DS46*CF$47/$DS$47 -> 0.015625 | CG46: =$DS46*CG$47/$DS$47 -> 0.03125 | CH46: =$DS46*CH$47/$DS$47 -> 0.03125 | CI46: =$DS46*CI$47/$DS$47 -> 0.03125 | CJ46: =$DS46*CJ$47/$DS$47 -> 0.015625 | CK46: =$DS46*CK$47/$DS$47 -> 0.046875 | ... DR46: =$DS46*DR$47/$DS$47 -> 0.015625 | DS46: 1
A47: 66 | B47: 11 | C47: 38 | E47: Marginal | F47: =SUM(F4:F46) -> 3 | G47: =SUM(G4:G46) -> 4 | H47: =SUM(H4:H46) -> 4 | I47: =SUM(I4:I46) -> 2 | J47: =SUM(J4:J46) -> 2 | K47: =SUM(K4:K46) -> 3 | L47: =SUM(L4:L46) -> 5 | M47: =SUM(M4:M46) -> 4 | ... O47: =SUM(O4:O46) -> 2 | P47: =SUM(F47:O47) -> 32 | S47: Marginal | T47: 11 | U47: 6 | V47: 5 | W47: 8 | X47: 5 | Y47: 5 | Z47: 4 | AA47: 5 | AB47: 7 | AC47: 8 | AD47: 64 | AI47: Marginal | AJ47: =SUM(AJ4:AJ46) -> 0 | AK47: =SUM(AK4:AK46) -> 0 | AL47: =SUM(AL4:AL46) -> 1 | AM47: =SUM(AM4:AM46) -> 1 | AN47: =SUM(AN4:AN46) -> 2 | AO47: =SUM(AO4:AO46) -> 2 | AP47: =SUM(AP4:AP46) -> 1 | AQ47: =SUM(AQ4:AQ46) -> 1 | ... BX47: =SUM(BX4:BX46) -> 1 | BY47: =SUM(AJ47:BX47) -> 37 | CC47: Marginal | CD47: 1 | CE47: 1 | CF47: 1 | CG47: 2 | CH47: 2 | CI47: 2 | CJ47: 1 | CK47: 3 | CL47: 1 | CM47: 2 | CN47: 2 | CO47: 1 | CP47: 2 | CQ47: 2 | CR47: 1 | CS47: 3 | CT47: 2 | CU47: 1 | CV47: 2 | CW47: 1 | CX47: 1 | CY47: 2 | CZ47: 1 | DA47: 1 | DB47: 3 | DC47: 1 | DD47: 3 | DE47: 2 | DF47: 1 | DG47: 1 | DH47: 3 | DI47: 2 | DJ47: 1 | DK47: 1 | DL47: 1 | DM47: 2 | DN47: 1 | DO47: 1 | DP47: 1 | DQ47: 1 | DR47: 1 | DS47: 64
A48: 90 | B48: 3 | C48: 80
A49: 20 | B49: 7 | C49: 57
A50: 66 | B50: 15 | C50: 47
A51: 43 | B51: 15 | C51: 71
A52: 55 | B52: 20 | C52: 52
A53: 47 | B53: 12 | C53: 27
A54: 61 | B54: 5 | C54: 25
A55: 47 | B55: 10 | C55: 69
A56: 73 | B56: 1 | C56: 23
A57: 50 | B57: 4 | C57: 21
A58: 66 | B58: 11 | C58: 78
A59: 59 | B59: 8 | C59: 79
...

Sheet Linear Regression
A1: Y(Age) | B1: X(Rank) | Q1: Age of the 160th
A2: 48 | B2: 1 | Q2: =_xlfn.FORECAST.LINEAR(160,A2:A65,B2:B65) -> 86.235577
A3: 31 | B3: 2
A4: 73 | B4: 3
A5: 31 | B5: 4
A6: 55 | B6: 5
A7: 36 | B7: 6
A8: 30 | B8: 7
A9: 31 | B9: 8
A10: 34 | B10: 9
A11: 42 | B11: 10
A12: 43 | B12: 11
A13: 19 | B13: 12
A14: 57 | B14: 13
... A65: 57 | B65: 64
